Workbook

Sheet SOFP-CuNonCu
B1: 01/01/YYYY - 31/12/YYYY | C1: 01/01/YYYY - 31/12/YYYY | D1: Source
A3: Statement of financial position
A4: Statement of financial position
A5: Statement of financial position
A6: Assets
A7: Non-current assets
A8: *Property, plant and equipment | B8: ='SOFP-Sub-CuNonCu'!B39 | C8: ='SOFP-Sub-CuNonCu'!C39
A9: *Investment property | B9: ='SOFP-Sub-CuNonCu'!B49 | C9: ='SOFP-Sub-CuNonCu'!C49
A10: Biological assets
A11: Right-of-use assets | B11: 19524288 | C11: 13076097 | D11: Page 16, Right-of-use assets
A12: Service concession assets
A13: *Intangible assets | B13: ='SOFP-Sub-CuNonCu'!B69 | C13: ='SOFP-Sub-CuNonCu'!C69
A14: *Investments in subsidiaries | B14: ='SOFP-Sub-CuNonCu'!B77 | C14: ='SOFP-Sub-CuNonCu'!C77
A15: *Investments in associates | B15: ='SOFP-Sub-CuNonCu'!B86 | C15: ='SOFP-Sub-CuNonCu'!C86
A16: *Investments in joint ventures | B16: ='SOFP-Sub-CuNonCu'!B95 | C16: ='SOFP-Sub-CuNonCu'!C95
A17: *Other investments | B17: 924204 | C17: 1008204 | D17: Page 16, Other assets (non-current). Placed here to ensure inclusion in Total Assets sum due to template B22 formula issue.
A18: *Trade and other non-current receivables | B18: ='SOFP-Sub-CuNonCu'!B120 | C18: ='SOFP-Sub-CuNonCu'!C120
A19: Contract assets
A20: Deferred tax assets | B20: 6998 | C20: 0 | D20: Page 16, Deferred tax assets
A21: *Derivative financial assets | B21: ='SOFP-Sub-CuNonCu'!B129 | C21: ='SOFP-Sub-CuNonCu'!C129
A22: *Other non-current assets | B22: ='SOFP-Sub-CuNonCu'!B198 | C22: ='SOFP-Sub-CuNonCu'!C198
A23: *Total non-current assets | B23: =1*B8+1*B9+1*B10+1*B11+1*B12+1*B13+1*B14+1*B15+1*B16+1*B17+1*B18+1*B19+1*B20+1*B21+1*B22 | C23: =1*C8+1*C9+1*C10+1*C11+1*C12+1*C13+1*C14+1*C15+1*C16+1*C17+1*C18+1*C19+1*C20+1*C21+1*C22
A24: Current assets
A25: *Inventories | B25: ='SOFP-Sub-CuNonCu'!B136 | C25: ='SOFP-Sub-CuNonCu'!C136
A26: Biological assets
A27: Other investments | B27: 5438139 | C27: 5329513 | D27: Page 16, Short term investments
A28: Current tax assets | B28: 497096 | C28: 2014561 | D28: Page 16, Current tax assets
A29: *Trade and other current receivables | B29: ='SOFP-Sub-CuNonCu'!B169 | C29: ='SOFP-Sub-CuNonCu'!C169
A30: Contract assets
A31: *Derivative financial assets | B31: ='SOFP-Sub-CuNonCu'!B178 | C31: ='SOFP-Sub-CuNonCu'!C178
A32: *Cash and cash equivalents | B32: ='SOFP-Sub-CuNonCu'!B193 | C32: ='SOFP-Sub-CuNonCu'!C193
A33: *Other current assets
A34: Total current assets other than assets held for sale | B34: =1*B25+1*B26+1*B27+1*B28+1*B29+1*B30+1*B31+1*B32+1*B33 | C34: =1*C25+1*C26+1*C27+1*C28+1*C29+1*C30+1*C31+1*C32+1*C33
A35: Non-current assets or disposal groups classified as held for sale or as held for distribution to owners
A36: *Total current assets | B36: =1*B25+1*B26+1*B27+1*B28+1*B29+1*B30+1*B31+1*B32+1*B33+1*B35 | C36: =1*C25+1*C26+1*C27+1*C28+1*C29+1*C30+1*C31+1*C32+1*C33+1*C35
A37: *Total assets | B37: =1*B8+1*B9+1*B11+1*B12+1*B13+1*B14+1*B15+1*B16+1*B17+1*B18+1*B19+1*B20+1*B21+1*B22+1*B25+1*B27+1*B28+1*B29+1*B30+1*B31+1*B32+1*B33+1*B35+1*B26+1*B10 | C37: =1*C8+1*C9+1*C11+1*C12+1*C13+1*C14+1*C15+1*C16+1*C17+1*C18+1*C19+1*C20+1*C21+1*C22+1*C25+1*C27+1*C28+1*C29+1*C30+1*C31+1*C32+1*C33+1*C35+1*C26+1*C10
A38: Equity and liabilities
A39: Equity
A40: *Issued capital | B40: ='SOFP-Sub-CuNonCu'!B203 | C40: ='SOFP-Sub-CuNonCu'!C203
A41: *Retained earnings | B41: 367463131 | C41: 334189137 | D41: Page 16, Retained earnings
...

Sheet SOFP-Sub-CuNonCu
B1: 01/01/YYYY - 31/12/YYYY | C1: 01/01/YYYY - 31/12/YYYY | D1: Source
A3: Sub-classification of assets, liabilities and equity
A4: Statement on sub-classification of assets, liabilities and equity
A5: Statement on sub-classification of assets, liabilities and equity
A6: Sub-classification of assets, liabilities and equity
A7: Property, plant and equipment
A8: Land and buildings
A9: Land
A10: Freehold land
A11: Long term leasehold land | B11: 123176785 | C11: 124922976 | D11: Page 55, Leasehold land
A12: Short term leasehold land
A13: *Land | B13: =1*B10+1*B11+1*B12 | C13: =1*C10+1*C11+1*C12
A14: Buildings
A15: Building on freehold land | D15: Page 55, Freehold land and buildings
A16: Building on long term leasehold land | B16: 161844458 | C16: 166552509 | D16: Page 55, Leasehold buildings
A17: Building on short term leasehold land
A18: Leased properties
A19: Total buildings | B19: =1*B15+1*B16+1*B17+1*B18 | C19: =1*C15+1*C16+1*C17+1*C18
A20: *Total land and buildings | B20: =1*B13+1*B19 | C20: =1*C13+1*C19
A21: Vehicles
A22: Vessels
A23: Aircraft
A24: Motor vehicles | B24: 23259576 | C24: 20860498 | D24: Page 55, Motor vehicles
A25: Other vehicles
A26: *Total vehicles | B26: =1*B22+1*B23+1*B24+1*B25 | C26: =1*C22+1*C23+1*C24+1*C25
A27: Machinery
A28: Plant and equipment | B28: 26066561 | C28: 30273924 | D28: Page 55, Plant and machinery
A29: Office equipment, fixture and fittings | B29: 13010753 | C29: 12374699 | D29: Page 55, Office equipment, furniture and fittings
A30: Computer software and hardware
A31: Bearer plants
A32: Infrastructure and site facilities
A33: Mining assets
A34: Oil and gas assets
A35: Tangible exploration and evaluation assets
A36: Telecommunication equipments
A37: Construction in progress/Asset work-in progress
A38: Other property, plant and equipment | B38: 44612073 | C38: 21634508 | D38: Page 55, Air conditioners, office renovation and pallets
A39: *Total property, plant and equipment | B39: =1*B20+1*B26+1*B27+1*B28+1*B29+1*B30+1*B31+1*B32+1*B33+1*B34+1*B35+1*B36+1*B37+1*B38 | C39: =1*C20+1*C26+1*C27+1*C28+1*C29+1*C30+1*C31+1*C32+1*C33+1*C34+1*C35+1*C36+1*C37+1*C38
A40: Investment property
A41: Investment properties completed, at carrying value
...

Sheet SOPL-Function
B1: 01/01/YYYY - 31/12/YYYY | C1: 01/01/YYYY - 31/12/YYYY | D1: Source
A3: Statement of profit or loss, by function of expense
A4: Statement of Profit or Loss
A5: Statement of profit or loss
A6: Continuing operations
A7: *Revenue | B7: ='SOPL-Analysis-Function'!B40 | C7: ='SOPL-Analysis-Function'!C40
A8: *Cost of sales | B8: ='SOPL-Analysis-Function'!B47 | C8: ='SOPL-Analysis-Function'!C47
A9: *Gross profit | B9: =1*B7+-1*B8 | C9: =1*C7+-1*C8
A10: *Other income | B10: ='SOPL-Analysis-Function'!B90 | C10: ='SOPL-Analysis-Function'!C90
A11: Selling and distribution expenses
A12: *Administrative expenses | B12: 75369006 | C12: 71956154 | D12: Page 18, Total 77,098,623 less Analysis-Other-Expenses 5,142,469
A13: Research and development expense
A14: *Other expenses | B14: ='SOPL-Analysis-Function'!B134 | C14: ='SOPL-Analysis-Function'!C134
A15: *Profit (loss) from operating activities | B15: =1*B7+-1*B8+1*B10+-1*B11+-1*B12+-1*B13+-1*B14 | C15: =1*C7+-1*C8+1*C10+-1*C11+-1*C12+-1*C13+-1*C14
A16: *Finance income | B16: ='SOPL-Analysis-Function'!B138 | C16: ='SOPL-Analysis-Function'!C138
A17: *Finance costs | B17: 14396928 | C17: 18347594 | D17: Page 18
A18: Share of profit (loss) of associates and joint ventures accounted for using equity method | B18: 291946 | C18: -302060 | D18: Page 18
A19: Fair valuation gain (loss) arising from distribution of non-cash assets to owners
A20: *Profit (loss) before tax | B20: =1*B7+-1*B8+1*B10+-1*B11+-1*B12+-1*B13+-1*B14+1*B16+-1*B17+1*B18+1*B19 | C20: =1*C7+-1*C8+1*C10+-1*C11+-1*C12+-1*C13+-1*C14+1*C16+-1*C17+1*C18+1*C19
A21: *Tax expense | B21: 17020092 | C21: 10691638 | D21: Page 18
A22: Contribution of zakat
A23: *Profit (loss) from continuing operations | B23: =1*B20+-1*B21+-1*B22 | C23: =1*C20+-1*C21+-1*C22
A24: Discontinued operations
A25: Profit (loss) from discontinued operations, net of tax
A26: *Profit (loss) | B26: =1*B23+1*B25 | C26: =1*C23+1*C25
A27: Profit (loss), attributable to
A28: Profit (loss), attributable to owners of parent | B28: 41273994 | C28: 8891310 | D28: Page 19
A29: Profit (loss) attributable to equity other components
A30: Profit (loss), attributable to non-controlling interests | B30: 2395318 | C30: 1014833 | D30: Page 19
A31: *Total profit (loss) | B31: =1*B28+1*B29+1*B30 | C31: =1*C28+1*C29+1*C30
A32: Earnings per share
A33: Basic earnings per share
A34: Basic earnings (loss) per share from continuing operations | B34: 5.16 | C34: 1.11 | D34: Page 19
A35: Basic earnings (loss) per share from discontinued operations
A36: *Total basic earnings (loss) per share | B36: =1*B35 | C36: =1*C35
A37: Diluted earnings per share
A38: Diluted earnings (loss) per share from continuing operations
A39: Diluted earnings (loss) per share from discontinued operations
A40: *Total diluted earnings (loss) per share | B40: =1*B39 | C40: =1*C39

Sheet SOPL-Analysis-Function
B1: 01/01/YYYY - 31/12/YYYY | C1: 01/01/YYYY - 31/12/YYYY | D1: Source
A3: Analysis of profit or loss, by function of expense
A4: Analysis of profit or loss
A5: Statement of profit or loss
A6: Revenue
A7: Revenue from sale of goods
A8: Revenue from sale of broadband and telecommunication
A9: Revenue from property development
A10: Revenue from construction contracts
A11: Revenue from clean water, treatment and disposal of waste water
A12: Revenue from sale of food and beverage
A13: Revenue from sale of agricultural produce
A14: Revenue from sale of oil and gas products
A15: Revenue from sale of other goods
A16: Total revenue from sale of goods | B16: =1*B8+1*B9+1*B10+1*B11+1*B12+1*B13+1*B14+1*B15 | C16: =1*C8+1*C9+1*C10+1*C11+1*C12+1*C13+1*C14+1*C15
A17: Revenue from rendering of services
A18: Revenue from rendering of entertainment services
A19: Revenue from rendering of telecommunication services
A20: Revenue from rendering of transport services
A21: Revenue from rendering of information technology services
A22: Revenue from rendering of educational services
A23: Revenue from rendering of healthcare services
A24: Revenue from rendering of shipping and shipping related services
A25: Revenue from rendering of other services | B25: 946612167 | C25: 747438303 | D25: Page 18, Statement of Comprehensive Income
A26: Total revenue from rendering of services | B26: =1*B18+1*B19+1*B20+1*B21+1*B22+1*B23+1*B24+1*B25 | C26: =1*C18+1*C19+1*C20+1*C21+1*C22+1*C23+1*C24+1*C25
A27: Interest income | D27: Moving to Misc to ensure inclusion in total
A28: Interest income on loans, advances and financing
A29: Interest income on other financial assets
A30: Total interest income | B30: =1*B28+1*B29 | C30: =1*C28+1*C29
A31: Other fee and commission income
A32: Gross brokerage and other charges
A33: Underwriting commissions and fund management income
A34: Other fee and commission income
A35: Total other fee and commission income | B35: =1*B32+1*B33+1*B34 | C35: =1*C32+1*C33+1*C34
A36: Dividend income
A37: Rental income
A38: Royalty income
A39: Other revenue
A40: *Total revenue | B40: =1*B16+1*B26+1*B30+1*B35+1*B36+1*B37+1*B38+1*B39 | C40: =1*C16+1*C26+1*C30+1*C35+1*C36+1*C37+1*C38+1*C39
A41: Cost of sales
...

Sheet SOCI-NetOfTax
B1: 01/01/YYYY - 31/12/YYYY | C1: 01/01/YYYY - 31/12/YYYY | D1: Source
A3: Statement of comprehensive income, net of tax
A4: Comprehensive income net of tax [abstract]
A5: Statement of comprehensive income net of tax [line items]
A6: Statement of comprehensive income [abstract]
A7: Profit (loss) | B7: 43669312 | C7: 9906143 | D7: Page 18, Profit for the year, Group 2020
A8: Other comprehensive income [abstract]
A9: Components of other comprehensive income that will not be reclassified to profit or loss, net of tax [abstract]
A10: Other comprehensive income, net of tax, gains (losses) on revaluation of property, plant and equipment, right-of-use assets and intangible assets
A11: Total other comprehensive income, net of tax, gains (losses) on remeasurements of defined benefit plans
A12: Other comprehensive income, net of tax, gains (losses) from investments in equity instruments
A13: Other comprehensive income, net of tax, gains (losses) on other items
A14: Share of other comprehensive income of associates and joint ventures accounted for using equity method that will not be reclassified to profit or loss, net of tax
A15: Total other comprehensive income that will not be reclassified to profit or loss, net of tax | B15: =1*B12+1*B13+1*B14 | C15: =1*C12+1*C13+1*C14
A16: Components of other comprehensive income that will be reclassified to profit or loss, net of tax [abstract]
A17: Cash flow hedges [abstract]
A18: Gains (losses) on cash flow hedges, net of tax | B18: 0 | C18: 10941 | D18: Page 18, Fair value adjustment on cash flow hedge, Group 2020
A19: Reclassification adjustments on cash flow hedges, net of tax
A20: Other comprehensive income, net of tax, cash flow hedges | B20: =1*B18+1*B19 | C20: =1*C18+1*C19
A21: Hedges of net investment in foreign operations [abstract]
A22: Gains (losses) on hedges of net investments in foreign operations, net of tax
A23: Reclassification adjustments on hedges of net investments in foreign operations, net of tax
A24: Other comprehensive income, net of tax, hedges of net investments in foreign operations | B24: =1*B22+1*B23 | C24: =1*C22+1*C23
A25: Exchange differences on translation [abstract]
A26: Gains (losses) on exchange differences on translation of foreign operations, net of tax | B26: 643844 | C26: -602165 | D26: Page 18, Exchange difference on translation of foreign operation, Group 2020
A27: Reclassification adjustments on exchange differences on translation of foreign operations, net of tax
A28: Other comprehensive income, net of tax, exchange differences on translation of foreign operations
A29: Financial assets measured at fair value through other comprehensive income [abstract]
A30: Gains (losses) on financial assets measured at fair value through other comprehensive income, net of tax
A31: Reclassification adjustments on financial assets measured at fair value through other comprehensive income, net of tax
A32: Amounts removed from equity and adjusted against fair value of financial assets on reclassification out of fair value through other comprehensive income measurement category, net of tax
A33: Other comprehensive income, net of tax, financial assets measured at fair value through other comprehensive income | B33: =1*B26+1*B27+1*B28+1*B30+1*B31+1*B32 | C33: =1*C26+1*C27+1*C28+1*C30+1*C31+1*C32
A34: Share of other comprehensive income of associates and joint ventures accounted for using equity method that will be reclassified to profit or loss, net of tax
A35: Others comprehensive income, net of tax, gains (losses) on other items | B35: 643844 | C35: -591224 | D35: Page 18, Total other comprehensive income for the year, net of tax (reclassifiable), Group 2020. Comprises Exchange difference (602,165) and Cash flow hedge 10,941.
A36: Total other comprehensive income that will be reclassified to profit or loss, net of tax | B36: =1*B34+1*B35 | C36: =1*C34+1*C35
A37: Total other comprehensive income | B37: =1*B11+1*B15+1*B36 | C37: =1*C11+1*C15+1*C36
A38: Total comprehensive income | B38: =1*B7+1*B37 | C38: =1*C7+1*C37
A39: Comprehensive income attributable to [abstract]
A40: Total comprehensive income, attributable to owners of parent | D40: Page 19, Total comprehensive income attributable to Owners of the Company, Group 2020
A41: Total comprehensive income, attributable to non-controlling interests | D41: Page 19, Total comprehensive income attributable to Non-controlling interests, Group 2020
...

Sheet SOCF-Indirect
B1: 01/01/YYYY - 31/12/YYYY | C1: 01/01/YYYY - 31/12/YYYY | D1: Source
A3: Statement of cash flows, indirect method
A4: Statement of cash flows
A5: Statement of cash flows
A6: Statement of cash flows
A7: Cash flows from (used in) operating activities
A8: *Profit (loss) before tax | B8: 60689404 | C8: 20597781 | D8: Page 22, Profit before tax
A9: *Total profit(loss) before tax | B9: =1*B8 | C9: =1*C8
A10: Adjustments to reconcile profit (loss)
A11: Adjustments for depreciation | B11: 39513711 | C11: 40680256 | D11: Page 22, Depreciation of PPE (31,002,867) + Depreciation of ROU assets (9,677,389)
A12: Adjustments for amortisation expense
A13: Adjustments for dividend income | B13: 36600 | C13: 0 | D13: Page 22, Dividend income
A14: Adjustments for equity settled share-based payment transactions
A15: Adjustments for changes in fair value of investment properties
A16: Adjustments for unrealised foreign exchange losses (gains) | B16: 2404500 | C16: -1219222 | D16: Page 22, Unrealised loss/(gain) on foreign exchange
A17: Adjustments for interest income | B17: 1201064 | C17: 3569988 | D17: Page 22, Interest income
A18: Adjustments for performance-based employee share scheme and other expenses
A19: Adjustments for share of profits of joint ventures (net of tax) | B19: -291946 | C19: 302060 | D19: Page 22, Share of results of associated company and joint venture (loss, so positive adjustment)
A20: Adjustments for share option expenses
A21: Adjustments for undistributed profits of associates
A22: Adjustments for finance costs | B22: 14396928 | C22: 18347594 | D22: Page 22, Interest expense
A23: Adjustments for finance income
A24: Short-term lease payments, payments for leases of low-value assets and variable lease payments not included in the measurement of the lease liability
A25: Adjustments for other non-current assets
A26: Adjustments for impairment loss (reversal of impairment loss) recognised in profit or loss
A27: Impairment (reversal of impairment) of property, plant and equipment
A28: Impairment (reversal of impairment) of investment properties
A29: Impairment (reversal of impairment) of prepaid lease rentals
A30: Impairment (reversal of impairment) of intangible assets
A31: Impairment (reversal of impairment) of investment in subsidiaries
A32: Impairment (reversal of impairment) of investment in associates
A33: Impairment (reversal of impairment) of investment in joint ventures
A34: Impairment (reversal of impairment) of other investments
A35: Impairment (reversal of impairment) of other financial assets or receivables | B35: 362401 | C35: 702780 | D35: Page 22, Allowance for doubtful debts
A36: Total adjustment for impairment (reversal of impairment) | B36: =1*B28+1*B29+1*B30+1*B31+1*B32+1*B33+1*B34+1*B35 | C36: =1*C28+1*C29+1*C30+1*C31+1*C32+1*C33+1*C34+1*C35
A37: Adjustments for losses (gains) on disposal of non-current assets
A38: (Gain) loss on disposal of property, plant and equipment | B38: -809323 | C38: -648816 | D38: Page 22, Gain on disposal of property, plant and equipment
A39: (Gain) loss on disposal of investment properties
A40: Total gain (loss) on disposal of non-current assets | B40: =1*B38+1*B39 | C40: =1*C38+1*C39
A41: (Gain) loss on disposal of subsidiaries | B41: 824860 | C41: 0 | D41: Page 22, Loss on derecognition of subsidiary
...

Sheet SOCIE
B1: 01/01/YYYY - 31/12/YYYY
B2: Issued capital | C2: Retained earnings | D2: Treasury shares | E2: Capital reserve | F2: Hedging reserve | G2: Foreign currency translation reserve | H2: Reserve of share-based payments | I2: Revaluation surplus | J2: Statutory reserve | K2: Warrant reserve | L2: Other non-distributable reserves | M2: Sub-total of non-distributable reserves | N2: Fair value reserve | O2: Reserve of non-current assets classified as held for sale | P2: Consolidation reserve | Q2: Warranty reserve | R2: Other distributable reserves | S2: Sub-Total of distributable reserves | T2: Reserves | U2: Equity attributable to owners | V2: Equity, others components | W2: Non-controlling interests | X2: Total
A3: Statement of changes in equity
A4: Statement of changes in equity
A5: Statement of changes in equity
A6: *Equity at beginning of period | B6: 100801317 | C6: 334189137 | M6: =SUM(E6:L6) | S6: =SUM(N6:R6) | T6: =M6+S6 | U6: =B6+C6+D6+T6 | X6: =U6+V6+W6
A7: *Impact of changes in accounting policies | M7: =SUM(E7:L7) | S7: =SUM(N7:R7) | T7: =M7+S7 | U7: =B7+C7+D7+T7 | X7: =U7+V7+W7
A8: *Equity at beginning of period, restated | B8: =B6+B7 | C8: =C6+C7 | D8: =D6+D7 | E8: =E6+E7 | F8: =F6+F7 | G8: =G6+G7 | H8: =H6+H7 | I8: =I6+I7 | ... L8: =L6+L7 | M8: =SUM(E8:L8) | N8: =N6+N7 | O8: =O6+O7 | P8: =P6+P7 | Q8: =Q6+Q7 | R8: =R6+R7 | S8: =SUM(N8:R8) | T8: =M8+S8 | U8: =B8+C8+D8+T8 | V8: =V6+V7 | W8: =W6+W7 | X8: =U8+V8+W8
A9: Changes in equity
A10: Comprehensive income
A11: *Profit (loss) | C11: 41273994 | M11: =SUM(E11:L11) | S11: =SUM(N11:R11) | T11: =M11+S11 | U11: =B11+C11+D11+T11 | X11: =U11+V11+W11
A12: *Total other comprehensive income | M12: =SUM(E12:L12) | S12: =SUM(N12:R12) | T12: =M12+S12 | U12: =B12+C12+D12+T12 | X12: =U12+V12+W12
A13: *Total comprehensive income | B13: =B11+B12 | C13: =C11+C12 | D13: =D11+D12 | E13: =E11+E12 | F13: =F11+F12 | G13: =G11+G12 | H13: =H11+H12 | I13: =I11+I12 | ... L13: =L11+L12 | M13: =SUM(E13:L13) | N13: =N11+N12 | O13: =O11+O12 | P13: =P11+P12 | Q13: =Q11+Q12 | R13: =R11+R12 | S13: =SUM(N13:R13) | T13: =M13+S13 | U13: =B13+C13+D13+T13 | V13: =V11+V12 | W13: =W11+W12 | X13: =U13+V13+W13
A14: Contributions by and distributions to owners
A15: Acquisition (dilution) of equity interest in subsidiaries | M15: =SUM(E15:L15) | S15: =SUM(N15:R15) | T15: =M15+S15 | U15: =B15+C15+D15+T15 | X15: =U15+V15+W15
A16: Arising from conversion of Irredeemable Convertible Unsecured Loan Stock (ICULS) | M16: =SUM(E16:L16) | S16: =SUM(N16:R16) | T16: =M16+S16 | U16: =B16+C16+D16+T16 | X16: =U16+V16+W16
A17: Dividends paid | C17: 8000000 | M17: =SUM(E17:L17) | S17: =SUM(N17:R17) | T17: =M17+S17 | U17: =B17+C17+D17+T17 | X17: =U17+V17+W17
A18: Issuance of shares | M18: =SUM(E18:L18) | S18: =SUM(N18:R18) | T18: =M18+S18 | U18: =B18+C18+D18+T18 | X18: =U18+V18+W18
A19: Issue of convertible notes, net of tax | M19: =SUM(E19:L19) | S19: =SUM(N19:R19) | T19: =M19+S19 | U19: =B19+C19+D19+T19 | X19: =U19+V19+W19
A20: Increase (decrease) through share-based payment transactions, equity | M20: =SUM(E20:L20) | S20: =SUM(N20:R20) | T20: =M20+S20 | U20: =B20+C20+D20+T20 | X20: =U20+V20+W20
A21: Treasury shares transactions | M21: =SUM(E21:L21) | S21: =SUM(N21:R21) | T21: =M21+S21 | U21: =B21+C21+D21+T21 | X21: =U21+V21+W21
A22: Other transactions with owners | M22: =SUM(E22:L22) | S22: =SUM(N22:R22) | T22: =M22+S22 | U22: =B22+C22+D22+T22 | X22: =U22+V22+W22
A23: Increase (decrease) through other changes, equity | M23: =SUM(E23:L23) | S23: =SUM(N23:R23) | T23: =M23+S23 | U23: =B23+C23+D23+T23 | X23: =U23+V23+W23
A24: *Total increase (decrease) in equity | B24: =1*B13+1*B15+1*B16+-1*B17+1*B18+1*B19+1*B20+1*B21+1*B22+1*B23 | C24: =1*C13+1*C15+1*C16+-1*C17+1*C18+1*C19+1*C20+1*C21+1*C22+1*C23 | D24: =1*D13+1*D15+1*D16+-1*D17+1*D18+1*D19+1*D20+1*D21+1*D22+1*D23 | E24: =1*E13+1*E15+1*E16+-1*E17+1*E18+1*E19+1*E20+1*E21+1*E22+1*E23 | F24: =1*F13+1*F15+1*F16+-1*F17+1*F18+1*F19+1*F20+1*F21+1*F22+1*F23 | G24: =1*G13+1*G15+1*G16+-1*G17+1*G18+1*G19+1*G20+1*G21+1*G22+1*G23 | H24: =1*H13+1*H15+1*H16+-1*H17+1*H18+1*H19+1*H20+1*H21+1*H22+1*H23 | I24: =1*I13+1*I15+1*I16+-1*I17+1*I18+1*I19+1*I20+1*I21+1*I22+1*I23 | ... L24: =1*L13+1*L15+1*L16+-1*L17+1*L18+1*L19+1*L20+1*L21+1*L22+1*L23 | M24: =SUM(E24:L24) | N24: =1*N13+1*N15+1*N16+-1*N17+1*N18+1*N19+1*N20+1*N21+1*N22+1*N23 | O24: =1*O13+1*O15+1*O16+-1*O17+1*O18+1*O19+1*O20+1*O21+1*O22+1*O23 | P24: =1*P13+1*P15+1*P16+-1*P17+1*P18+1*P19+1*P20+1*P21+1*P22+1*P23 | Q24: =1*Q13+1*Q15+1*Q16+-1*Q17+1*Q18+1*Q19+1*Q20+1*Q21+1*Q22+1*Q23 | R24: =1*R13+1*R15+1*R16+-1*R17+1*R18+1*R19+1*R20+1*R21+1*R22+1*R23 | S24: =SUM(N24:R24) | T24: =M24+S24 | U24: =B24+C24+D24+T24 | V24: =1*V13+1*V15+1*V16+-1*V17+1*V18+1*V19+1*V20+1*V21+1*V22+1*V23 | W24: =1*W13+1*W15+1*W16+-1*W17+1*W18+1*W19+1*W20+1*W21+1*W22+1*W23 | X24: =U24+V24+W24
A25: *Equity at end of period | B25: =B8+B24 | C25: =C8+C24 | D25: =D8+D24 | E25: =E8+E24 | F25: =F8+F24 | G25: =G8+G24 | H25: =H8+H24 | I25: =I8+I24 | ... L25: =L8+L24 | M25: =SUM(E25:L25) | N25: =N8+N24 | O25: =O8+O24 | P25: =P8+P24 | Q25: =Q8+Q24 | R25: =R8+R24 | S25: =SUM(N25:R25) | T25: =M25+S25 | U25: =B25+C25+D25+T25 | V25: =V8+V24 | W25: =W8+W24 | X25: =U25+V25+W25
A27: Statement of changes in equity
A28: Statement of changes in equity
A29: Statement of changes in equity
A30: *Equity at beginning of period | M30: =SUM(E30:L30) | S30: =SUM(N30:R30) | T30: =M30+S30 | U30: =B30+C30+D30+T30 | X30: =U30+V30+W30
A31: *Impact of changes in accounting policies | M31: =SUM(E31:L31) | S31: =SUM(N31:R31) | T31: =M31+S31 | U31: =B31+C31+D31+T31 | X31: =U31+V31+W31
A32: *Equity at beginning of period, restated | B32: =B30+B31 | C32: =C30+C31 | D32: =D30+D31 | E32: =E30+E31 | F32: =F30+F31 | G32: =G30+G31 | H32: =H30+H31 | I32: =I30+I31 | ... L32: =L30+L31 | M32: =SUM(E32:L32) | N32: =N30+N31 | O32: =O30+O31 | P32: =P30+P31 | Q32: =Q30+Q31 | R32: =R30+R31 | S32: =SUM(N32:R32) | T32: =M32+S32 | U32: =B32+C32+D32+T32 | V32: =V30+V31 | W32: =W30+W31 | X32: =U32+V32+W32
A33: Changes in equity
A34: Comprehensive income
A35: *Profit (loss) | M35: =SUM(E35:L35) | S35: =SUM(N35:R35) | T35: =M35+S35 | U35: =B35+C35+D35+T35 | X35: =U35+V35+W35
A36: *Total other comprehensive income | M36: =SUM(E36:L36) | S36: =SUM(N36:R36) | T36: =M36+S36 | U36: =B36+C36+D36+T36 | X36: =U36+V36+W36
A37: *Total comprehensive income | B37: =B35+B36 | C37: =C35+C36 | D37: =D35+D36 | E37: =E35+E36 | F37: =F35+F36 | G37: =G35+G36 | H37: =H35+H36 | I37: =I35+I36 | ... L37: =L35+L36 | M37: =SUM(E37:L37) | N37: =N35+N36 | O37: =O35+O36 | P37: =P35+P36 | Q37: =Q35+Q36 | R37: =R35+R36 | S37: =SUM(N37:R37) | T37: =M37+S37 | U37: =B37+C37+D37+T37 | V37: =V35+V36 | W37: =W35+W36 | X37: =U37+V37+W37
A38: Contributions by and distributions to owners
A39: Acquisition (dilution) of equity interest in subsidiaries | M39: =SUM(E39:L39) | S39: =SUM(N39:R39) | T39: =M39+S39 | U39: =B39+C39+D39+T39 | X39: =U39+V39+W39
A40: Arising from conversion of Irredeemable Convertible Unsecured Loan Stock (ICULS) | M40: =SUM(E40:L40) | S40: =SUM(N40:R40) | T40: =M40+S40 | U40: =B40+C40+D40+T40 | X40: =U40+V40+W40
A41: Dividends paid | C41: 5000000 | M41: =SUM(E41:L41) | S41: =SUM(N41:R41) | T41: =M41+S41 | U41: =B41+C41+D41+T41 | X41: =U41+V41+W41
...
