Workbook
Name CountryList: Data!$O$1:$O$246
Name CurrencyList: Data!$Q$1:$Q$172
Name NewCurrencyList: Data!$Q$1:$Q$172
Name ScaleList: [1]StartUp!$L$1:$L$5
Name ScaleList: [2]StartUp!$L$1:$L$5
Name UnitList: [1]StartUp!$K$1:$K$172
Name UnitList: [2]StartUp!$K$1:$K$172

Sheet Introduction

Sheet Content Page
B2: Content Page
B3: More Options (Document Actions)
B4: Financial Statements as per Malaysian Financial Reporting Standards - 1.0
B5: General
B6: Filing Information
B8: Disclosure
B9: Scope of filing
B10: Disclosure - Directors report
B11: Disclosure - Director business review
B12: Disclosure - Statement by directors
B13: Disclosure - Involvement in Stock Exchange
B14: Disclosure - Auditors report to members
... B30: Notes - Related party transactions

Sheet FilingInfo
A1: 529ff12d-e989-41d3-b834-6513adcedc61:~:AtleastOneValueInAnyLayout:~:True:~:<?xml version="1.0" encoding="utf-16"?>_x000D_ <Customization xmlns:xsi="http://www.w3.org/2001/XMLSchema-instance" xmlns:xsd="http://www.w3.org/2001/XMLSchema" ComparitiveDate="False" LayoutByDate="False" LayoutByCompany="False" ShowAllDomains="False" TotalDomain="True" DefaultDates="1" />:~:http://xbrl.ssm.com.my/role/ssm/rol_ssmt-dei-fs-mfrs_2022-12-31/ssmt-dei-fs-mfrs_2022-12-31_role-010000:~:None
D2: FS-MFRS Filing Information
D3: * denotes mandatory items to be reported | E3: Edit Filing Information
C5: 9113df73-46c5-408f-9235-ab46a26a4c6e:~:FilingInfo_1:~:NotMandatory:~:False:~:0:~:True:~:<?xml version="1.0" encoding="utf-16"?>_x000D_ <Customization xmlns:xsi="http://www.w3.org/2001/XMLSchema-instance" xmlns:xsd="http://www.w3.org/2001/XMLSchema" ComparitiveDate="False" LayoutByDate="False" LayoutByCompany="False" ShowAllDomains="False" TotalDomain="True" DefaultDates="1" />:~:LytLin:~::~:False:~:True:~:ssmt-dei-cor_2022-12-31.xsd#ssmt-dei_FilingInformationAbstract@http://www.xbrl.org/2003/role/label:~:
C8: #LAYOUTSCSR# | D8: #PRIM# | F8: #TABLE# | G8: #LAYOUTECSR#
C9: #TABLE#
A10: ssmt-dei-cor_2022-12-31.xsd#ssmt-dei_FilingInformationAbstract | D10: Filing Information
A11: ssmt-dei-cor_2022-12-31.xsd#ssmt-dei_GeneralFilingInformationAbstract | D11: General Filing Information
A12: ssmt-dei-cor_2022-12-31.xsd#ssmt-dei_NewCompanyRegistrationNumber | D12: *New Company registration number | E12: 197501000529
A13: ssmt-dei-cor_2022-12-31.xsd#ssmt-dei_CompanyRegistrationNumber | D13: Company registration number
A14: ssmt-dei-cor_2022-12-31.xsd#ssmt-dei_NameOfReportingEntity | D14: *Name of company | E14: AMWAY (MALAYSIA) SDN BHD
A15: ssmt-dei-cor_2022-12-31.xsd#ssmt-dei_FormerNameOfCompany | D15: Former name of the company
A16: ssmt-dei-cor_2022-12-31.xsd#ssmt-dei_OriginOfCompany | D16: *Origin of company | E16: Incorporated in Malaysia
A17: ssmt-dei-cor_2022-12-31.xsd#ssmt-dei_StatusOfCompany | D17: *Status of company | E17: Private company
A18: ssmt-dei-cor_2022-12-31.xsd#ssmt-dei_TypeOfCompany | D18: *Types of company | E18: Company limited by shares
A19: ssmt-dei-cor_2022-12-31.xsd#ssmt-dei_ApplicationOfSubmission | D19: *Application of submission | E19: Ordinary filing
A20: ssmt-dei-cor_2022-12-31.xsd#ssmt-dei_StatutoryDeclarationForRectification | D20: Statutory Declaration for rectification
A21: ssmt-dei-cor_2022-12-31.xsd#ssmt-dei_CourtOrderReferenceNumber | D21: Court Order reference number
A22: ssmt-dei-cor_2022-12-31.xsd#ssmt-dei_DisclosureOfFinancialStatementsPreparationForCurrentSubmission | D22: *Disclosure of financial statements preparation for current submission | E22: Subsequent preparation of financial statements
A23: ssmt-dei-cor_2022-12-31.xsd#ssmt-dei_CompanyCurrentFinancialYearStartDate | D23: *Company's current financial year start date | E23: 01/01/2024
A24: ssmt-dei-cor_2022-12-31.xsd#ssmt-dei_CompanyCurrentFinancialYearEndDate | D24: *Company's current financial year end date | E24: 31/12/2024
A25: ssmt-dei-cor_2022-12-31.xsd#ssmt-dei_CompanyPreviousFinancialYearStartDate | D25: Company's previous financial year start date | E25: 01/01/2023
A26: ssmt-dei-cor_2022-12-31.xsd#ssmt-dei_CompanyPreviousFinancialYearEndDate | D26: Company's previous financial year end date | E26: 31/12/2023
A27: ssmt-dei-cor_2022-12-31.xsd#ssmt-dei_StatusOfCarryingOnBusinessDuringFinancialYear | D27: *Status of carrying on business during the financial year | E27: Carrying on business activities
A28: ssmt-dei-cor_2022-12-31.xsd#ssmt-dei_DisclosureOfFinancialStatementsAuditStatus | D28: *Disclosure of financial statements audit status | E28: Audited
A29: ssmt-dei-cor_2022-12-31.xsd#ssmt-dei_AuditExemptionCategory | D29: Audit exemption category
A30: ssmt-dei-cor_2022-12-31.xsd#ssmt-dei_BasisOfAccountingStandardsAppliedToPrepareFinancialStatements | D30: *Basis of accounting standards applied to prepare the financial statements | E30: Malaysian Financial Reporting Standards
A31: ssmt-dei-cor_2022-12-31.xsd#ssmt-dei_DisclosureOfOtherAccountingStandardsApplied | D31: Disclosure of other accounting standards applied
A32: ssmt-dei-cor_2022-12-31.xsd#ssmt-dei_TypeOfSubmission | D32: *Type of submission | E32: FS-MFRS
A33: ssmt-dei-ee-mfrs_2022-12-31.xsd#ssmt-dei-ee-mfrs_NatureOfFinancialStatements | D33: *Nature of financial statements | E33: Separate
A34: ssmt-dei-cor_2022-12-31.xsd#ssmt-dei_DescriptionOfPresentationCurrency | D34: *Description of presentation currency | E34: Malaysian Ringgit (MYR)
A35: ssmt-dei-cor_2022-12-31.xsd#ssmt-dei_DescriptionOfFunctionalCurrency | D35: Description of functional currency
A36: ssmt-dei-cor_2022-12-31.xsd#ssmt-dei_LevelOfRoundingUsedInFinancialStatements | D36: *Level of rounding used in financial statements | E36: In thousands ('000')
A37: ssmt-dei-cor_2022-12-31.xsd#ssmt-dei_NameAndVersionOfSoftwareUsedToGenerateXBRLFile | D37: *Name and version of software used to generate XBRL file | E37: MBRS_Preparation_Tool v2.2
A38: ssmt-dei-cor_2022-12-31.xsd#ssmt-dei_TaxonomyVersion | D38: *Taxonomy version | E38: SSMxT_2022v1.0
C39: #TABLE#
C40: #LAYOUTSCER# | G40: #LAYOUTECER#

Sheet SOF
A1: c6385edc-8d86-45a1-a751-bbee2d4934b0:~:AtleastOneValueInAnyLayout:~:True:~:<?xml version="1.0" encoding="utf-16"?>_x000D_ <Customization xmlns:xsi="http://www.w3.org/2001/XMLSchema-instance" xmlns:xsd="http://www.w3.org/2001/XMLSchema" ComparitiveDate="False" LayoutByDate="False" LayoutByCompany="False" ShowAllDomains="True" TotalDomain="False" DefaultDates="1" />:~:http://xbrl.ssm.com.my/role/ssm/rol_ssmt-fs-mfrs_2022-12-31/ssmt-fs-mfrs_2022-12-31_role-020000:~:None
D2: FS-MFRS Scope of filing
D3: * denotes mandatory items to be reported
C5: 2020b569-fbf5-4c8c-8b47-a5af94d1af0e:~:SOF_1:~:NotMandatory:~:False:~:0:~:True:~:<?xml version="1.0" encoding="utf-16"?>_x000D_ <Customization xmlns:xsi="http://www.w3.org/2001/XMLSchema-instance" xmlns:xsd="http://www.w3.org/2001/XMLSchema" ComparitiveDate="False" LayoutByDate="False" LayoutByCompany="False" ShowAllDomains="True" TotalDomain="False" DefaultDates="1" />:~:LytLin:~::~:False:~:True:~:ssmt-cor_2022-12-31.xsd#ssmt_DisclosureOnScopeOfFilingAbstract@http://www.xbrl.org/2003/role/label:~:
C8: #LAYOUTSCSR# | D8: #PRIM# | F8: #TABLE# | G8: #LAYOUTECSR#
C9: #STDTENDTDATE# | E9: =TEXT(DATE(MID(E10,7,4),MID(E10,4,2),MID(E10,1,2)),"dd/MM/yyyy")&" - "&TEXT(DATE(MID(E11,7,4),MID(E11,4,2),MID(E11,1,2)),"dd/MM/yyyy") -> 01/01/2024 - 31/12/2024
C10: #STDT# | E10: =StartUp!$D$8 -> 01/01/2024
C11: #ENDT# | E11: =StartUp!$D$9 -> 31/12/2024
C12: #TABLE#
A13: ssmt-cor_2022-12-31.xsd#ssmt_DisclosureOnScopeOfFilingAbstract | D13: Disclosure on scope of filing
A14: ssmt-cor_2022-12-31.xsd#ssmt_ParticularsOfFinancialStatementsAndReportsAbstract | D14: Particulars of Financial Statements and Reports
A15: ssmt-cor_2022-12-31.xsd#ssmt_DateOfFinancialStatementsApprovedByBoardOfDirectors | D15: *Date of financial statements approved by Board of Directors
A16: ssmt-cor_2022-12-31.xsd#ssmt_DateOfCirculationOfFinancialStatementsAndReportsToMembers | D16: *Date of circulation of financial statements and reports to members
A17: ssmt-cor_2022-12-31.xsd#ssmt_DateOfFinancialStatementsAndReportsOfDirectorsAndAuditorsLaidInAnnualGeneralMeeting | D17: Date of financial statements and reports of the directors and auditors (if applicable) laid in annual general meeting
A18: ssmt-cor_2022-12-31.xsd#ssmt_DateOfStatutoryDeclaration | D18: *Date of Statutory Declaration
A19: ssmt-cor_2022-12-31.xsd#ssmt_DisclosureOnWhetherCompanysSharesAreTradedOnAnyOfficialStockExchange | D19: Disclosure on whether company's shares are traded on any official stock exchange | E19: Listed
A20: ssmt-cor_2022-12-31.xsd#ssmt_DisclosureOfRegulationAppliedDuringIncorporationOfCompany | D20: Disclosure of the regulation applied during incorporation of the company
A21: ssmt-cor_2022-12-31.xsd#ssmt_DisclosureOnWhetherCompanyInvolvedAsManagementCompanyUnderInterestSchemeAct2016 | D21: Disclosure on whether company involved as management company under Interest Scheme Act 2016
A22: ssmt-cor_2022-12-31.xsd#ssmt_DisclosureOfWhetherCompanyRegulatedByBankNegaraMalaysiaAtFinancialYearEnd | D22: Disclosure of whether company regulated by Bank Negara Malaysia at the financial year end | E22: Company not regulated by Bank Negara Malaysia
C23: #TABLE#
C24: #LAYOUTSCER# | G24: #LAYOUTECER#
C28: e84081cf-ebb2-4f52-aba7-69a29a01f856:~:SOF_2:~:NotMandatory:~:False:~:1:~:True:~:<?xml version="1.0" encoding="utf-16"?>_x000D_ <Customization xmlns:xsi="http://www.w3.org/2001/XMLSchema-instance" xmlns:xsd="http://www.w3.org/2001/XMLSchema" ComparitiveDate="False" LayoutByDate="False" LayoutByCompany="False" ShowAllDomains="True" TotalDomain="False" DefaultDates="1" />:~:LytHyc:~:ssmt-cor_2022-12-31.xsd#ssmt_NatureOfBusinessTable:~:False:~:True:~:ssmt-cor_2022-12-31.xsd#ssmt_DisclosureOnScopeOfFilingAbstract@http://www.xbrl.org/2003/role/label::ssmt-cor_2022-12-31.xsd#ssmt_DetailsOfPrincipalActivitiesOfBusinessAbstract@http://www.xbrl.org/2003/role/label::ssmt-cor_2022-12-31.xsd#ssmt_NatureOfBusinessLineItems@http://www.xbrl.org/2003/role/label:~:ssmt-cor_2022-12-31.xsd#ssmt_NatureOfBusinessTable
E29: ssmt-cor_2022-12-31.xsd#ssmt_MSICCode | F29: ssmt-cor_2022-12-31.xsd#ssmt_DescriptionOfBusiness
D30: ssmt-cor_2022-12-31.xsd#ssmt_NatureOfBusinessTable::ssmt-cor_2022-12-31.xsd#ssmt_NatureOfBusinessAxis
C31: #LAYOUTSCSR# | D31: #DOM# | G31: #TABLE# | H31: #LAYOUTECSR#
C32: #PRIM# | E32: *MSIC Code | F32: *Description of business
C33: #STDTENDTDATE# | E33: =TEXT(DATE(MID(E34,7,4),MID(E34,4,2),MID(E34,1,2)),"dd/MM/yyyy")&" - "&TEXT(DATE(MID(E35,7,4),MID(E35,4,2),MID(E35,1,2)),"dd/MM/yyyy") -> 01/01/2024 - 31/12/2024 | F33: =TEXT(DATE(MID(F34,7,4),MID(F34,4,2),MID(F34,1,2)),"dd/MM/yyyy")&" - "&TEXT(DATE(MID(F35,7,4),MID(F35,4,2),MID(F35,1,2)),"dd/MM/yyyy") -> 01/01/2024 - 31/12/2024
C34: #STDT# | E34: =StartUp!$D$8 -> 01/01/2024 | F34: =StartUp!$D$8 -> 01/01/2024
C35: #ENDT# | E35: =StartUp!$D$9 -> 31/12/2024 | F35: =StartUp!$D$9 -> 31/12/2024
C36: #TABLE#
B37: ssmt-cor_2022-12-31.xsd#ssmt_NatureOfBusinessTable::ssmt-cor_2022-12-31.xsd#ssmt_NatureOfBusinessAxis::ssmt-cor_2022-12-31.xsd#ssmt_BusinessOneMember | D37: Business 1
B38: ssmt-cor_2022-12-31.xsd#ssmt_NatureOfBusinessTable::ssmt-cor_2022-12-31.xsd#ssmt_NatureOfBusinessAxis::ssmt-cor_2022-12-31.xsd#ssmt_BusinessTwoMember | D38: Business 2
B39: ssmt-cor_2022-12-31.xsd#ssmt_NatureOfBusinessTable::ssmt-cor_2022-12-31.xsd#ssmt_NatureOfBusinessAxis::ssmt-cor_2022-12-31.xsd#ssmt_BusinessThreeMember | D39: Business 3
C40: #TABLE#
C41: #LAYOUTSCER# | H41: #LAYOUTECER#
C45: 2fb1de5a-7652-43fb-9d2d-73c5a08a683b:~:SOF_3:~:NotMandatory:~:False:~:2:~:True:~:<?xml version="1.0" encoding="utf-16"?>_x000D_ <Customization xmlns:xsi="http://www.w3.org/2001/XMLSchema-instance" xmlns:xsd="http://www.w3.org/2001/XMLSchema" ComparitiveDate="False" LayoutByDate="False" LayoutByCompany="False" ShowAllDomains="True" TotalDomain="False" DefaultDates="1" />:~:LytLin:~::~:False:~:True:~:ssmt-cor_2022-12-31.xsd#ssmt_DisclosureOnScopeOfFilingAbstract@http://www.xbrl.org/2003/role/label:~:
C48: #LAYOUTSCSR# | D48: #PRIM# | F48: #TABLE# | G48: #LAYOUTECSR#
C49: #STDTENDTDATE# | E49: =TEXT(DATE(MID(E50,7,4),MID(E50,4,2),MID(E50,1,2)),"dd/MM/yyyy")&" - "&TEXT(DATE(MID(E51,7,4),MID(E51,4,2),MID(E51,1,2)),"dd/MM/yyyy") -> 01/01/2024 - 31/12/2024
C50: #STDT# | E50: =StartUp!$D$8 -> 01/01/2024
C51: #ENDT# | E51: =StartUp!$D$9 -> 31/12/2024
...

Sheet DirectorsRep
A1: 89b682df-712f-4e49-99ae-3acf6481ec99:~:AtleastOneValueInAnyLayout:~:True:~:<?xml version="1.0" encoding="utf-16"?>_x000D_ <Customization xmlns:xsi="http://www.w3.org/2001/XMLSchema-instance" xmlns:xsd="http://www.w3.org/2001/XMLSchema" ComparitiveDate="False" LayoutByDate="False" LayoutByCompany="False" ShowAllDomains="False" TotalDomain="True" DefaultDates="1" />:~:http://xbrl.ssm.com.my/role/ssm/rol_ssmt-fs-mfrs_2022-12-31/ssmt-fs-mfrs_2022-12-31_role-120000:~:None
D2: FS-MFRS Disclosure - Directors report
D3: * denotes mandatory items to be reported
C5: 13a921b6-de34-4a64-8117-dc7f972fcf23:~:DirectorsRep_1:~:NotMandatory:~:False:~:0:~:True:~:<?xml version="1.0" encoding="utf-16"?>_x000D_ <Customization xmlns:xsi="http://www.w3.org/2001/XMLSchema-instance" xmlns:xsd="http://www.w3.org/2001/XMLSchema" ComparitiveDate="False" LayoutByDate="False" LayoutByCompany="False" ShowAllDomains="False" TotalDomain="True" DefaultDates="1" />:~:LytLin:~::~:False:~:True:~:ssmt-cor_2022-12-31.xsd#ssmt_DisclosureOnDirectorsReportAbstract@http://www.xbrl.org/2003/role/label:~:
C8: #LAYOUTSCSR# | D8: #PRIM# | F8: #TABLE# | G8: #LAYOUTECSR#
C9: #STDTENDTDATE# | E9: =TEXT(DATE(MID(E10,7,4),MID(E10,4,2),MID(E10,1,2)),"dd/MM/yyyy")&" - "&TEXT(DATE(MID(E11,7,4),MID(E11,4,2),MID(E11,1,2)),"dd/MM/yyyy") -> 01/01/2024 - 31/12/2024
C10: #STDT# | E10: =StartUp!$D$8 -> 01/01/2024
C11: #ENDT# | E11: =StartUp!$D$9 -> 31/12/2024
C12: #TABLE#
A13: ssmt-cor_2022-12-31.xsd#ssmt_DisclosureOnDirectorsReportAbstract | D13: Disclosure on directors report
A14: ssmt-cor_2022-12-31.xsd#ssmt_DirectorsReportAbstract | D14: Director's Report
A15: ssmt-cor_2022-12-31.xsd#ssmt_DisclosureOfDirectorsReportExplanatory | D15: *Disclosure of Director's Report
A16: ssmt-cor_2022-12-31.xsd#ssmt_NumberOfDirectorsSigningDirectorsReport | D16: *Number of directors signing Director's report
A17: ssmt-cor_2022-12-31.xsd#ssmt_NameOfFirstDirectorWhoSignedDirectorsReport | D17: *Name of first director who signed Director's report
A18: ssmt-cor_2022-12-31.xsd#ssmt_TypeOfIdentificationOfFirstDirectorWhoSignedDirectorsReport | D18: *Type of identification of first director who signed director's report
A19: ssmt-cor_2022-12-31.xsd#ssmt_IdentificationNumberOfFirstDirectorWhoSignedDirectorsReport | D19: *Identification number of the first director who signed director's report
A20: ssmt-cor_2022-12-31.xsd#ssmt_NameOfSecondDirectorWhoSignedDirectorsReport | D20: Name of second director who signed the director's report
A21: ssmt-cor_2022-12-31.xsd#ssmt_TypeOfIdentificationOfSecondDirectorWhoSignedDirectorsReport | D21: Type of identification of second director who signed Director's report
A22: ssmt-cor_2022-12-31.xsd#ssmt_IdentificationNumberOfSecondDirectorWhoSignedDirectorsReport | D22: Identification number of the second director who signed director's report
A23: ssmt-cor_2022-12-31.xsd#ssmt_NameOfThirdDirectorWhoSignedDirectorsReport | D23: Name of third director who signed the director's report
A24: ssmt-cor_2022-12-31.xsd#ssmt_TypeOfIdentificationOfThirdDirectorWhoSignedDirectorsReport | D24: Type of identification of third director who signed Director's report
... A36: ssmt-cor_2022-12-31.xsd#ssmt_DateOfSigningDirectorsReport | D36: *Date of signing director's report
C37: #TABLE#
C38: #LAYOUTSCER# | G38: #LAYOUTECER#

Sheet DirectorsBussRev
A1: 6afd2ff7-526b-4c4e-8a46-10a5234226a2:~:AtleastOneValueInAnyLayout:~:True:~:<?xml version="1.0" encoding="utf-16"?>_x000D_ <Customization xmlns:xsi="http://www.w3.org/2001/XMLSchema-instance" xmlns:xsd="http://www.w3.org/2001/XMLSchema" ComparitiveDate="False" LayoutByDate="False" LayoutByCompany="False" ShowAllDomains="False" TotalDomain="True" DefaultDates="1" />:~:http://xbrl.ssm.com.my/role/ssm/rol_ssmt-fs-mfrs_2022-12-31/ssmt-fs-mfrs_2022-12-31_role-120200:~:None
D2: FS-MFRS Disclosure - Director business review
D3: * denotes mandatory items to be reported
C5: fc01c29c-f543-4291-afce-4e8c7f2f2fa9:~:DirectorsBussRev_1:~:NotMandatory:~:False:~:0:~:True:~:<?xml version="1.0" encoding="utf-16"?>_x000D_ <Customization xmlns:xsi="http://www.w3.org/2001/XMLSchema-instance" xmlns:xsd="http://www.w3.org/2001/XMLSchema" ComparitiveDate="False" LayoutByDate="False" LayoutByCompany="False" ShowAllDomains="False" TotalDomain="True" DefaultDates="1" />:~:LytLin:~::~:False:~:True:~:ssmt-cor_2022-12-31.xsd#ssmt_DisclosureOnDirectorsBusinessReviewAbstract@http://www.xbrl.org/2003/role/label:~:
C8: #LAYOUTSCSR# | D8: #PRIM# | F8: #TABLE# | G8: #LAYOUTECSR#
C9: #STDTENDTDATE# | E9: =TEXT(DATE(MID(E10,7,4),MID(E10,4,2),MID(E10,1,2)),"dd/MM/yyyy")&" - "&TEXT(DATE(MID(E11,7,4),MID(E11,4,2),MID(E11,1,2)),"dd/MM/yyyy") -> 01/01/2024 - 31/12/2024
C10: #STDT# | E10: =StartUp!$D$8 -> 01/01/2024
C11: #ENDT# | E11: =StartUp!$D$9 -> 31/12/2024
C12: #TABLE#
A13: ssmt-cor_2022-12-31.xsd#ssmt_DisclosureOnDirectorsBusinessReviewAbstract | D13: Disclosure on directors business review
A14: ssmt-cor_2022-12-31.xsd#ssmt_DisclosureOfStatementByDirectorsForBusinessReviewExplanatory | D14: Disclosure of statement by directors for business review
A15: ssmt-cor_2022-12-31.xsd#ssmt_DisclosureOfBusinessReviewEitherOnEnvironmentEmployeesOrSocialAndCommunityIssues | D15: Disclosure of business review either on environmental, employees or social and community issues
A16: ssmt-cor_2022-12-31.xsd#ssmt_EnvironmentalMatters | D16: Environmental matters
A17: ssmt-cor_2022-12-31.xsd#ssmt_CompanysEmployees | D17: Company's employees
A18: ssmt-cor_2022-12-31.xsd#ssmt_SocialAndCommunityIssues | D18: Social and community issues
A19: ssmt-cor_2022-12-31.xsd#ssmt_Others | D19: Others
A20: ssmt-cor_2022-12-31.xsd#ssmt_DisclosureOfOtherBusinessReviewApplied | D20: Disclosure of other business review applied
A21: ssmt-cor_2022-12-31.xsd#ssmt_DetailsOfCompanyEmployeesAbstract | D21: Details of company's employees
A22: ssmt-cor_2022-12-31.xsd#ssmt_NumberOfEmployees | D22: *Number of employees
C23: #TABLE#
C24: #LAYOUTSCER# | G24: #LAYOUTECER#

Sheet StatOfDirectors
A1: 478c4afb-57d6-43a8-b34d-80bb9ccf96ee:~:AtleastOneValueInAnyLayout:~:True:~:<?xml version="1.0" encoding="utf-16"?>_x000D_ <Customization xmlns:xsi="http://www.w3.org/2001/XMLSchema-instance" xmlns:xsd="http://www.w3.org/2001/XMLSchema" ComparitiveDate="False" LayoutByDate="False" LayoutByCompany="False" ShowAllDomains="False" TotalDomain="True" DefaultDates="1" />:~:http://xbrl.ssm.com.my/role/ssm/rol_ssmt-fs-mfrs_2022-12-31/ssmt-fs-mfrs_2022-12-31_role-120100:~:None
D2: FS-MFRS Disclosure - Statement by directors
D3: * denotes mandatory items to be reported
C5: f0b350e2-fc54-40bd-bf29-d3e422671aed:~:StatOfDirectors_1:~:NotMandatory:~:False:~:0:~:True:~:<?xml version="1.0" encoding="utf-16"?>_x000D_ <Customization xmlns:xsi="http://www.w3.org/2001/XMLSchema-instance" xmlns:xsd="http://www.w3.org/2001/XMLSchema" ComparitiveDate="False" LayoutByDate="False" LayoutByCompany="False" ShowAllDomains="False" TotalDomain="True" DefaultDates="1" />:~:LytLin:~::~:False:~:True:~:ssmt-cor_2022-12-31.xsd#ssmt_DisclosureOnStatementByDirectorsAbstract@http://www.xbrl.org/2003/role/label:~:
C8: #LAYOUTSCSR# | D8: #PRIM# | F8: #TABLE# | G8: #LAYOUTECSR#
C9: #STDTENDTDATE# | E9: =TEXT(DATE(MID(E10,7,4),MID(E10,4,2),MID(E10,1,2)),"dd/MM/yyyy")&" - "&TEXT(DATE(MID(E11,7,4),MID(E11,4,2),MID(E11,1,2)),"dd/MM/yyyy") -> 01/01/2024 - 31/12/2024
C10: #STDT# | E10: =StartUp!$D$8 -> 01/01/2024
C11: #ENDT# | E11: =StartUp!$D$9 -> 31/12/2024
C12: #TABLE#
A13: ssmt-cor_2022-12-31.xsd#ssmt_DisclosureOnStatementByDirectorsAbstract | D13: Disclosure on statement by directors
A14: ssmt-cor_2022-12-31.xsd#ssmt_StatementOfDirectorsAbstract | D14: Statement by Directors
A15: ssmt-cor_2022-12-31.xsd#ssmt_DisclosureOfStatementByDirectorsExplanatory | D15: *Disclosure of Statement by Directors
A16: ssmt-cor_2022-12-31.xsd#ssmt_DisclosureOfDirectorsOpinionThatFinancialStatementsOrConsolidatedFinancialStatementsAreDrawnInAccordanceWithAccountingStandards | D16: *Disclosure of directors opinion that the financial statements or consolidated financial statements are drawn up in accordance with approved accounting standards and reflect true and give true and fair view of financial position and performance of the company and the group
A17: ssmt-cor_2022-12-31.xsd#ssmt_NumberOfDirectorsSigningStatementByDirectors | D17: *Number of directors signing Statement by Directors
A18: ssmt-cor_2022-12-31.xsd#ssmt_NameOfFirstDirectorWhoSignedStatementByDirectors | D18: *Name of first director who signed Statement by Directors
A19: ssmt-cor_2022-12-31.xsd#ssmt_DisclosureWhetherFirstDirectorIsAlsoPrimarilyResponsibleForFinancialManagementOfCompany | D19: *Disclosure whether the first director is also primarily responsible for financial management of the company
A20: ssmt-cor_2022-12-31.xsd#ssmt_TypeOfIdentificationOfFirstDirectorWhoSignedStatementByDirectors | D20: *Type of identification of first director who signed Statement by Directors
A21: ssmt-cor_2022-12-31.xsd#ssmt_IdentificationNumberOfFirstDirectorWhoSignedStatementByDirectors | D21: *Identification number of the first director who signed Statement by Directors
A22: ssmt-cor_2022-12-31.xsd#ssmt_NameOfSecondDirectorWhoSignedStatementByDirectors | D22: Name of second director who signed Statement by Directors
A23: ssmt-cor_2022-12-31.xsd#ssmt_DisclosureWhetherSecondDirectorIsAlsoPrimarilyResponsibleForFinancialManagementOfCompany | D23: Disclosure whether the second director is also primarily responsible for financial management of the company
A24: ssmt-cor_2022-12-31.xsd#ssmt_TypeOfIdentificationNumberOfSecondDirectorWhoSignedStatementByDirectors | D24: Type of identification of second director who signed Statement by Directors
... A41: ssmt-cor_2022-12-31.xsd#ssmt_DateOfSigningStatementByDirectors | D41: *Date of signing statement by directors
C42: #TABLE#
C43: #LAYOUTSCER# | G43: #LAYOUTECER#

Sheet InvolInSE
A1: 3fe565c1-c031-4ec7-9463-cf017f8b82af:~:AtleastOneValueInAnyLayout:~:True:~:<?xml version="1.0" encoding="utf-16"?>_x000D_ <Customization xmlns:xsi="http://www.w3.org/2001/XMLSchema-instance" xmlns:xsd="http://www.w3.org/2001/XMLSchema" ComparitiveDate="False" LayoutByDate="False" LayoutByCompany="False" ShowAllDomains="False" TotalDomain="True" DefaultDates="1" />:~:http://xbrl.ssm.com.my/role/ssm/rol_ssmt-fs-mfrs_2022-12-31/ssmt-fs-mfrs_2022-12-31_role-110000:~:None
D2: FS-MFRS Disclosure - Involvement in Stock Exchange
D3: * denotes mandatory items to be reported(PLEASE IGNORE IF COMPANY NOT-LISTED)
C5: 4077ddfd-f5ed-4932-9436-b025d0f11874:~:InvolInSE_1:~:NotMandatory:~:False:~:0:~:True:~:<?xml version="1.0" encoding="utf-16"?>_x000D_ <Customization xmlns:xsi="http://www.w3.org/2001/XMLSchema-instance" xmlns:xsd="http://www.w3.org/2001/XMLSchema" ComparitiveDate="False" LayoutByDate="False" LayoutByCompany="False" ShowAllDomains="False" TotalDomain="True" DefaultDates="1" />:~:LytLin:~::~:False:~:True:~:ssmt-cor_2022-12-31.xsd#ssmt_DisclosureOnInvolvementInStockExchangeAbstract@http://www.xbrl.org/2003/role/label:~:
C8: #LAYOUTSCSR# | D8: #PRIM# | F8: #TABLE# | G8: #LAYOUTECSR#
C9: #STDTENDTDATE# | E9: =TEXT(DATE(MID(E10,7,4),MID(E10,4,2),MID(E10,1,2)),"dd/MM/yyyy")&" - "&TEXT(DATE(MID(E11,7,4),MID(E11,4,2),MID(E11,1,2)),"dd/MM/yyyy") -> 01/01/2024 - 31/12/2024
C10: #STDT# | E10: =StartUp!$D$8 -> 01/01/2024
C11: #ENDT# | E11: =StartUp!$D$9 -> 31/12/2024
C12: #TABLE#
A13: ssmt-cor_2022-12-31.xsd#ssmt_DisclosureOnInvolvementInStockExchangeAbstract | D13: Disclosure on involvement in stock exchange
A14: ssmt-cor_2022-12-31.xsd#ssmt_DateOfCompanyListedOnStockExchange | D14: *Date of company listed in Stock Exchange
A15: ssmt-cor_2022-12-31.xsd#ssmt_TypeOfExchangeOnWhichCompanyIsListed | D15: *Type of exchange on which company is listed
A16: ssmt-cor_2022-12-31.xsd#ssmt_DisclosureOfForeignStockExchange | D16: Disclosure of foreign stock exchange
A17: ssmt-cor_2022-12-31.xsd#ssmt_TypeOfMarketListedOnBursaMalaysia | D17: Type of market listed in Bursa Malaysia
A18: ssmt-cor_2022-12-31.xsd#ssmt_DisclosureOfSecuritiesListingOnShariahCompliantSecuritiesList | D18: *Disclosure of securities listing on Shari’ah compliant Securities list
A19: ssmt-cor_2022-12-31.xsd#ssmt_ExplanationOfOtherSecuritiesListedOnShariahComplaintSecuritiesList | D19: Explanation of other securities listed on Shari’ah compliant Securities list
A20: ssmt-cor_2022-12-31.xsd#ssmt_DateOfDelistingOfShares | D20: Date of delisting of shares
A21: ssmt-cor_2022-12-31.xsd#ssmt_TypeOfExchangeFromWhichSharesWereDelisted | D21: Type of exchange from which shares were delisted
A22: ssmt-cor_2022-12-31.xsd#ssmt_DisclosureOfForeignStockExchangeWhichCompanyWereDelisted | D22: Disclosure of foreign stock exchange which the company were delisted
C23: #TABLE#
C24: #LAYOUTSCER# | G24: #LAYOUTECER#

Sheet AuditReport
A1: 535ddd76-6156-4b07-a746-c5e13fd8d5ba:~:AtleastOneValueInAnyLayout:~:True:~:<?xml version="1.0" encoding="utf-16"?>_x000D_ <Customization xmlns:xsi="http://www.w3.org/2001/XMLSchema-instance" xmlns:xsd="http://www.w3.org/2001/XMLSchema" ComparitiveDate="False" LayoutByDate="False" LayoutByCompany="False" ShowAllDomains="False" TotalDomain="True" DefaultDates="1" />:~:http://xbrl.ssm.com.my/role/ssm/rol_ssmt-fs-mfrs_2022-12-31/ssmt-fs-mfrs_2022-12-31_role-130000:~:None
D2: FS-MFRS Disclosure - Auditors report to members
D3: * denotes mandatory items to be reported
D4: Auditor's details are mandatory to be reported only if 'Audited' is selected in the Filing Information
C5: bd4ef598-d3ef-4ad8-a6e6-f28d1446ee17:~:AuditReport_1:~:NotMandatory:~:False:~:0:~:True:~:<?xml version="1.0" encoding="utf-16"?>_x000D_ <Customization xmlns:xsi="http://www.w3.org/2001/XMLSchema-instance" xmlns:xsd="http://www.w3.org/2001/XMLSchema" ComparitiveDate="False" LayoutByDate="False" LayoutByCompany="False" ShowAllDomains="False" TotalDomain="True" DefaultDates="1" />:~:LytLin:~::~:False:~:True:~:ssmt-cor_2022-12-31.xsd#ssmt_DisclosureOnAuditorsReportToMembersAbstract@http://www.xbrl.org/2003/role/label:~:
C8: #LAYOUTSCSR# | D8: #PRIM# | F8: #TABLE# | G8: #LAYOUTECSR#
C9: #STDTENDTDATE# | E9: =TEXT(DATE(MID(E10,7,4),MID(E10,4,2),MID(E10,1,2)),"dd/MM/yyyy")&" - "&TEXT(DATE(MID(E11,7,4),MID(E11,4,2),MID(E11,1,2)),"dd/MM/yyyy") -> 01/01/2024 - 31/12/2024
C10: #STDT# | E10: =StartUp!$D$8 -> 01/01/2024
C11: #ENDT# | E11: =StartUp!$D$9 -> 31/12/2024
C12: #TABLE#
A13: ssmt-cor_2022-12-31.xsd#ssmt_DisclosureOnAuditorsReportToMembersAbstract | D13: Disclosure on auditors report to members
A14: ssmt-cor_2022-12-31.xsd#ssmt_AuditorsReportAbstract | D14: Auditor's report
A15: ssmt-cor_2022-12-31.xsd#ssmt_DisclosureOfAuditorsReportToMembersExplanatory | D15: *Disclosure of auditor's report to members
A16: ssmt-cor_2022-12-31.xsd#ssmt_TypeOfAuditorsOpinion | D16: *Type of auditor's opinion
A17: ssmt-cor_2022-12-31.xsd#ssmt_DateOfSigningAuditorsReport | D17: *Date of signing auditor's report
C18: #TABLE#
C19: #LAYOUTSCER# | G19: #LAYOUTECER#
C23: fb3d0ad8-129c-44d2-be07-233aa4d03efc:~:AuditReport_2:~:NotMandatory:~:False:~:1:~:True:~:<?xml version="1.0" encoding="utf-16"?>_x000D_ <Customization xmlns:xsi="http://www.w3.org/2001/XMLSchema-instance" xmlns:xsd="http://www.w3.org/2001/XMLSchema" ComparitiveDate="False" LayoutByDate="False" LayoutByCompany="False" ShowAllDomains="False" TotalDomain="True" DefaultDates="1" />:~:LytHyc:~:ssmt-cor_2022-12-31.xsd#ssmt_AuditorsInformationTable:~:False:~:True:~:ssmt-cor_2022-12-31.xsd#ssmt_DisclosureOnAuditorsReportToMembersAbstract@http://www.xbrl.org/2003/role/label::ssmt-cor_2022-12-31.xsd#ssmt_AuditorsInformationAbstract@http://www.xbrl.org/2003/role/label::ssmt-cor_2022-12-31.xsd#ssmt_AuditorsInformationLineitem@http://www.xbrl.org/2003/role/label:~:ssmt-cor_2022-12-31.xsd#ssmt_AuditorsInformationTable
E24: ssmt-cor_2022-12-31.xsd#ssmt_LicenseNumberOfAuditor | F24: ssmt-cor_2022-12-31.xsd#ssmt_NameOfAuditorSigningReport | G24: ssmt-cor_2022-12-31.xsd#ssmt_RegistrationNumberOfAuditFirm | H24: ssmt-cor_2022-12-31.xsd#ssmt_NameOfAuditFirm | I24: ssmt-cor_2022-12-31.xsd#ssmt_AddressOne | J24: ssmt-cor_2022-12-31.xsd#ssmt_AddressTwo | K24: ssmt-cor_2022-12-31.xsd#ssmt_AddressThree | L24: ssmt-cor_2022-12-31.xsd#ssmt_PostcodeOfAuditFirm | M24: ssmt-cor_2022-12-31.xsd#ssmt_TownWhereAuditFirmIsLocated | N24: ssmt-cor_2022-12-31.xsd#ssmt_StateWhereAuditFirmIsLocated
D25: ssmt-cor_2022-12-31.xsd#ssmt_AuditorsInformationTable::ssmt-cor_2022-12-31.xsd#ssmt_AuditorsCountAxis
C26: #LAYOUTSCSR# | D26: #DOM# | O26: #TABLE# | P26: #LAYOUTECSR#
C27: #PRIM# | E27: *License number of auditor | F27: *Name of auditor signing report | G27: *Registration number of audit firm | H27: *Name of audit firm | I27: *Address line 1 | J27: Address line 2 | K27: Address line 3 | L27: *Postcode | M27: *Town | N27: *State
C28: #STDTENDTDATE# | E28: =TEXT(DATE(MID(E29,7,4),MID(E29,4,2),MID(E29,1,2)),"dd/MM/yyyy")&" - "&TEXT(DATE(MID(E30,7,4),MID(E30,4,2),MID(E30,1,2)),"dd/MM/yyyy") -> 01/01/2024 - 31/12/2024 | F28: =TEXT(DATE(MID(F29,7,4),MID(F29,4,2),MID(F29,1,2)),"dd/MM/yyyy")&" - "&TEXT(DATE(MID(F30,7,4),MID(F30,4,2),MID(F30,1,2)),"dd/MM/yyyy") -> 01/01/2024 - 31/12/2024 | G28: =TEXT(DATE(MID(G29,7,4),MID(G29,4,2),MID(G29,1,2)),"dd/MM/yyyy")&" - "&TEXT(DATE(MID(G30,7,4),MID(G30,4,2),MID(G30,1,2)),"dd/MM/yyyy") -> 01/01/2024 - 31/12/2024 | H28: =TEXT(DATE(MID(H29,7,4),MID(H29,4,2),MID(H29,1,2)),"dd/MM/yyyy")&" - "&TEXT(DATE(MID(H30,7,4),MID(H30,4,2),MID(H30,1,2)),"dd/MM/yyyy") -> 01/01/2024 - 31/12/2024 | I28: =TEXT(DATE(MID(I29,7,4),MID(I29,4,2),MID(I29,1,2)),"dd/MM/yyyy")&" - "&TEXT(DATE(MID(I30,7,4),MID(I30,4,2),MID(I30,1,2)),"dd/MM/yyyy") -> 01/01/2024 - 31/12/2024 | J28: =TEXT(DATE(MID(J29,7,4),MID(J29,4,2),MID(J29,1,2)),"dd/MM/yyyy")&" - "&TEXT(DATE(MID(J30,7,4),MID(J30,4,2),MID(J30,1,2)),"dd/MM/yyyy") -> 01/01/2024 - 31/12/2024 | K28: =TEXT(DATE(MID(K29,7,4),MID(K29,4,2),MID(K29,1,2)),"dd/MM/yyyy")&" - "&TEXT(DATE(MID(K30,7,4),MID(K30,4,2),MID(K30,1,2)),"dd/MM/yyyy") -> 01/01/2024 - 31/12/2024 | L28: =TEXT(DATE(MID(L29,7,4),MID(L29,4,2),MID(L29,1,2)),"dd/MM/yyyy")&" - "&TEXT(DATE(MID(L30,7,4),MID(L30,4,2),MID(L30,1,2)),"dd/MM/yyyy") -> 01/01/2024 - 31/12/2024 | ... N28: =TEXT(DATE(MID(N29,7,4),MID(N29,4,2),MID(N29,1,2)),"dd/MM/yyyy")&" - "&TEXT(DATE(MID(N30,7,4),MID(N30,4,2),MID(N30,1,2)),"dd/MM/yyyy") -> 01/01/2024 - 31/12/2024
C29: #STDT# | E29: =StartUp!$D$8 -> 01/01/2024 | F29: =StartUp!$D$8 -> 01/01/2024 | G29: =StartUp!$D$8 -> 01/01/2024 | H29: =StartUp!$D$8 -> 01/01/2024 | I29: =StartUp!$D$8 -> 01/01/2024 | J29: =StartUp!$D$8 -> 01/01/2024 | K29: =StartUp!$D$8 -> 01/01/2024 | L29: =StartUp!$D$8 -> 01/01/2024 | ... N29: =StartUp!$D$8 -> 01/01/2024
C30: #ENDT# | E30: =StartUp!$D$9 -> 31/12/2024 | F30: =StartUp!$D$9 -> 31/12/2024 | G30: =StartUp!$D$9 -> 31/12/2024 | H30: =StartUp!$D$9 -> 31/12/2024 | I30: =StartUp!$D$9 -> 31/12/2024 | J30: =StartUp!$D$9 -> 31/12/2024 | K30: =StartUp!$D$9 -> 31/12/2024 | L30: =StartUp!$D$9 -> 31/12/2024 | ... N30: =StartUp!$D$9 -> 31/12/2024
C31: #TABLE# | E31: Insert only the first four digit from the full auditor's license number. e.g. XXXX/XX/XX(J/PH) | G31: Insert AF and the audit firm's four digit number from the full audit firm's number. e.g. AFXXXX
B32: 0 | D32: 0001
C33: #TABLE#
C34: #LAYOUTSCER# | P34: #LAYOUTECER#

Sheet SOFP-CuNonCu
A1: aba851e9-d688-4d30-856c-4f1919c2c24a:~:AtleastOneValueInAnyLayout:~:True:~:<?xml version="1.0" encoding="utf-16"?>_x000D_ <Customization xmlns:xsi="http://www.w3.org/2001/XMLSchema-instance" xmlns:xsd="http://www.w3.org/2001/XMLSchema" ComparitiveDate="False" LayoutByDate="False" LayoutByCompany="False" ShowAllDomains="False" TotalDomain="True" DefaultDates="2" />:~:http://xbrl.ssm.com.my/role/ssm/rol_ssmt-fs-mfrs_2022-12-31/ssmt-fs-mfrs_2022-12-31_role-200100x:~:None
D2: FS-MFRS Statement of financial position, by current/non-current method
D3: * denotes mandatory items to be reported
C5: 659bf83e-5dc1-467d-87cc-ef264eff1111:~:SOFP-CuNonCu_1_TBLYT:~:NotMandatory:~:False:~:0:~:True:~:<?xml version="1.0" encoding="utf-16"?>_x000D_ <Customization xmlns:xsi="http://www.w3.org/2001/XMLSchema-instance" xmlns:xsd="http://www.w3.org/2001/XMLSchema" ComparitiveDate="False" LayoutByDate="False" LayoutByCompany="False" ShowAllDomains="False" TotalDomain="True" DefaultDates="2" />:~:LytTxb:~::~:False:~:True:~:ssmt-cor_2022-12-31.xsd#ssmt_DisclosureOnStatementOfFinancialPositionAbstract@http://www.xbrl.org/2003/role/label:~:
C8: #LAYOUTSCSR# | D8: #PRIM# | F8: #TABLE# | G8: #LAYOUTECSR#
C9: #TABLE#
A10: ssmt-cor_2022-12-31.xsd#ssmt_DisclosureOnStatementOfFinancialPositionAbstract | D10: Disclosure on statement of financial position
C11: #TABLE#
C12: #LAYOUTSCER# | G12: #LAYOUTECER#
C15: df5a5fa2-5402-4eb0-8545-d71421aa44fb:~:SOFP-CuNonCu_2:~:NotMandatory:~:True:~:1:~:True:~:<?xml version="1.0" encoding="utf-16"?>_x000D_ <Customization xmlns:xsi="http://www.w3.org/2001/XMLSchema-instance" xmlns:xsd="http://www.w3.org/2001/XMLSchema" ComparitiveDate="False" LayoutByDate="False" LayoutByCompany="False" ShowAllDomains="False" TotalDomain="True" DefaultDates="2" />:~:LytHyc:~:ssmt-cor_2022-12-31.xsd#ssmt_StatementOfFinancialPositionTable:~:False:~:True:~:ssmt-cor_2022-12-31.xsd#ssmt_DisclosureOnStatementOfFinancialPositionAbstract@http://www.xbrl.org/2003/role/label::ssmt-cor_2022-12-31.xsd#ssmt_StatementOfFinancialPositionAbstract@http://www.xbrl.org/2003/role/label::ssmt-cor_2022-12-31.xsd#ssmt_StatementOfFinancialPositionLineItems@http://www.xbrl.org/2003/role/label:~:ssmt-cor_2022-12-31.xsd#ssmt_StatementOfFinancialPositionTable
C18: #LAYOUTSCSR# | D18: #PRIM# | G18: #TABLE# | H18: #LAYOUTECSR#
C19: #STDTENDTDATE# | E19: =TEXT(DATE(MID(E21,7,4),MID(E21,4,2),MID(E21,1,2)),"dd/MM/yyyy")&" - "&TEXT(DATE(MID(E22,7,4),MID(E22,4,2),MID(E22,1,2)),"dd/MM/yyyy") -> 01/01/2024 - 31/12/2024 | F19: =TEXT(DATE(MID(F21,7,4),MID(F21,4,2),MID(F21,1,2)),"dd/MM/yyyy")&" - "&TEXT(DATE(MID(F22,7,4),MID(F22,4,2),MID(F22,1,2)),"dd/MM/yyyy") -> 01/01/2023 - 31/12/2023
C20: #UNITSCALE# | E20: =StartUp!$E$8 -> MYR'000 | F20: =StartUp!$E$8 -> MYR'000
C21: #STDT# | E21: =StartUp!$D$8 -> 01/01/2024 | F21: =StartUp!$D$10 -> 01/01/2023
C22: #ENDT# | E22: =StartUp!$D$9 -> 31/12/2024 | F22: =StartUp!$D$11 -> 31/12/2023
C23: #TABLE#
A24: ssmt-cor_2022-12-31.xsd#ssmt_StatementOfFinancialPositionAbstract | D24: Statement of financial position
A25: ssmt-cor_2022-12-31.xsd#ssmt_StatementOfFinancialPositionLineItems | D25: Statement of financial position
A26: full_ifrs-cor_2022-03-24.xsd#ifrs-full_AssetsAbstract | D26: Assets
A27: full_ifrs-cor_2022-03-24.xsd#ifrs-full_NoncurrentAssetsAbstract | D27: Non-current assets
A28: full_ifrs-cor_2022-03-24.xsd#ifrs-full_PropertyPlantAndEquipment | D28: *Property, plant and equipment | E28: ='SOFP-Sub-CuNonCu'!E59 -> 1000000 | F28: ='SOFP-Sub-CuNonCu'!F59 -> 0 | G28: See details
A29: full_ifrs-cor_2022-03-24.xsd#ifrs-full_InvestmentProperty | D29: *Investment property | E29: ='SOFP-Sub-CuNonCu'!E69 -> 0 | F29: ='SOFP-Sub-CuNonCu'!F69 -> 0 | G29: See details
A30: ssmt-mfrs-cor_2022-12-31.xsd#ssmt-mfrs_NoncurrentBiologicalAssets@http://xbrl.ssm.com.my/role/ssm/lab_rol_ssmt-fs-mfrs_2022-12-31/ReportingLabel | D30: Biological assets
A31: full_ifrs-cor_2022-03-24.xsd#ifrs-full_RightofuseAssets@http://xbrl.ssm.com.my/role/ssm/lab_rol_ssmt-fs-mfrs_2022-12-31/ReportingLabel | D31: Right-of-use assets
A32: ssmt-mfrs-cor_2022-12-31.xsd#ssmt-mfrs_NoncurrentServiceConcessionAssets@http://xbrl.ssm.com.my/role/ssm/lab_rol_ssmt-fs-mfrs_2022-12-31/ReportingLabel | D32: Service concession assets
A33: full_ifrs-cor_2022-03-24.xsd#ifrs-full_IntangibleAssetsAndGoodwill@http://xbrl.ssm.com.my/role/ssm/lab_rol_ssmt-fs-mfrs_2022-12-31/ReportingLabel | D33: *Intangible assets | E33: ='SOFP-Sub-CuNonCu'!E89 -> 0 | F33: ='SOFP-Sub-CuNonCu'!F89 -> 0 | G33: See details
A34: full_ifrs-cor_2022-03-24.xsd#ifrs-full_InvestmentsInSubsidiaries@http://xbrl.ssm.com.my/role/ssm/lab_rol_ssmt-fs-mfrs_2022-12-31/ReportingLabel | D34: *Investments in subsidiaries | E34: ='SOFP-Sub-CuNonCu'!E97 -> 0 | F34: ='SOFP-Sub-CuNonCu'!F97 -> 0 | G34: See details
A35: full_ifrs-cor_2022-03-24.xsd#ifrs-full_InvestmentsInAssociates@http://xbrl.ssm.com.my/role/ssm/lab_rol_ssmt-fs-mfrs_2022-12-31/ReportingLabel | D35: *Investments in associates | E35: ='SOFP-Sub-CuNonCu'!E106 -> 0 | F35: ='SOFP-Sub-CuNonCu'!F106 -> 0 | G35: See details
A36: full_ifrs-cor_2022-03-24.xsd#ifrs-full_InvestmentsInJointVentures@http://xbrl.ssm.com.my/role/ssm/lab_rol_ssmt-fs-mfrs_2022-12-31/ReportingLabel | D36: *Investments in joint ventures | E36: ='SOFP-Sub-CuNonCu'!E115 -> 0 | F36: ='SOFP-Sub-CuNonCu'!F115 -> 0 | G36: See details
A37: full_ifrs-cor_2022-03-24.xsd#ifrs-full_NoncurrentInvestmentsOtherThanInvestmentsAccountedForUsingEquityMethod@http://xbrl.ssm.com.my/role/ssm/lab_rol_ssmt-fs-mfrs_2022-12-31/ReportingLabel | D37: *Other investments
A38: full_ifrs-cor_2022-03-24.xsd#ifrs-full_NoncurrentReceivables | D38: *Trade and other non-current receivables | E38: ='SOFP-Sub-CuNonCu'!E140 -> 0 | F38: ='SOFP-Sub-CuNonCu'!F140 -> 0 | G38: See details
A39: full_ifrs-cor_2022-03-24.xsd#ifrs-full_NoncurrentContractAssets@http://xbrl.ssm.com.my/role/ssm/lab_rol_ssmt-fs-mfrs_2022-12-31/ReportingLabel | D39: Contract assets
A40: full_ifrs-cor_2022-03-24.xsd#ifrs-full_DeferredTaxAssets | D40: Deferred tax assets
A41: full_ifrs-cor_2022-03-24.xsd#ifrs-full_NoncurrentDerivativeFinancialAssets@http://xbrl.ssm.com.my/role/ssm/lab_rol_ssmt-fs-mfrs_2022-12-31/ReportingLabel | D41: *Derivative financial assets | E41: ='SOFP-Sub-CuNonCu'!E149 -> 0 | F41: ='SOFP-Sub-CuNonCu'!F149 -> 0 | G41: See details
A42: full_ifrs-cor_2022-03-24.xsd#ifrs-full_OtherNoncurrentAssets | D42: *Other non-current assets | E42: ='SOFP-Sub-CuNonCu'!E218 -> 0 | F42: ='SOFP-Sub-CuNonCu'!F218 -> 0 | G42: See details
A43: full_ifrs-cor_2022-03-24.xsd#ifrs-full_NoncurrentAssets@http://www.xbrl.org/2003/role/totalLabel | D43: *Total non-current assets | E43: =1*E28+1*E29+1*E30+1*E31+1*E32+1*E33+1*E34+1*E35+1*E36+1*E37+1*E38+1*E39+1*E40+1*E41+1*E42 -> 1000000 | F43: =1*F28+1*F29+1*F30+1*F31+1*F32+1*F33+1*F34+1*F35+1*F36+1*F37+1*F38+1*F39+1*F40+1*F41+1*F42 -> 0
A44: full_ifrs-cor_2022-03-24.xsd#ifrs-full_CurrentAssetsAbstract | D44: Current assets
A45: full_ifrs-cor_2022-03-24.xsd#ifrs-full_InventoriesTotal | D45: *Inventories | E45: ='SOFP-Sub-CuNonCu'!E156 -> 0 | F45: ='SOFP-Sub-CuNonCu'!F156 -> 0 | G45: See details
A46: ssmt-mfrs-cor_2022-12-31.xsd#ssmt-mfrs_CurrentBiologicalAssets@http://xbrl.ssm.com.my/role/ssm/lab_rol_ssmt-fs-mfrs_2022-12-31/ReportingLabel | D46: Biological assets
A47: full_ifrs-cor_2022-03-24.xsd#ifrs-full_CurrentInvestments@http://xbrl.ssm.com.my/role/ssm/lab_rol_ssmt-fs-mfrs_2022-12-31/ReportingLabel | D47: Other investments
...

Sheet SOFP-Sub-CuNonCu
A1: c34185e3-d692-47ad-8a98-d791585875b8:~:AtleastOneValueInAnyLayout:~:True:~:<?xml version="1.0" encoding="utf-16"?>_x000D_ <Customization xmlns:xsi="http://www.w3.org/2001/XMLSchema-instance" xmlns:xsd="http://www.w3.org/2001/XMLSchema" ComparitiveDate="False" LayoutByDate="False" LayoutByCompany="False" ShowAllDomains="False" TotalDomain="True" DefaultDates="2" />:~:http://xbrl.ssm.com.my/role/ssm/rol_ssmt-fs-mfrs_2022-12-31/ssmt-fs-mfrs_2022-12-31_role-200200x:~:None
D2: FS-MFRS Sub-classification of assets, liabilities and equity, by current/non-current method
D3: * denotes mandatory items to be reported
C5: b9877f0c-4ab2-476f-b54d-a35a3e867c6a:~:SOFP-Sub-CuNonCu_1_TBLYT:~:NotMandatory:~:False:~:0:~:True:~:<?xml version="1.0" encoding="utf-16"?>_x000D_ <Customization xmlns:xsi="http://www.w3.org/2001/XMLSchema-instance" xmlns:xsd="http://www.w3.org/2001/XMLSchema" ComparitiveDate="False" LayoutByDate="False" LayoutByCompany="False" ShowAllDomains="False" TotalDomain="True" DefaultDates="2" />:~:LytTxb:~::~:False:~:True:~:ssmt-mfrs-cor_2022-12-31.xsd#ssmt-mfrs_DisclosureOnSubclassificationOfAssetsLiabilitiesAndEquityAbstract@http://www.xbrl.org/2003/role/label:~:
C8: #LAYOUTSCSR# | D8: #PRIM# | F8: #TABLE# | G8: #LAYOUTECSR#
C9: #TABLE#
A10: ssmt-mfrs-cor_2022-12-31.xsd#ssmt-mfrs_DisclosureOnSubclassificationOfAssetsLiabilitiesAndEquityAbstract | D10: Disclosure on sub-classification of assets, liabilities and equity
C11: #TABLE#
C12: #LAYOUTSCER# | G12: #LAYOUTECER#
C15: bee4d44c-2d67-4d65-9d5f-8f366adca267:~:SOFP-Sub-CuNonCu_2:~:NotMandatory:~:True:~:1:~:True:~:<?xml version="1.0" encoding="utf-16"?>_x000D_ <Customization xmlns:xsi="http://www.w3.org/2001/XMLSchema-instance" xmlns:xsd="http://www.w3.org/2001/XMLSchema" ComparitiveDate="False" LayoutByDate="False" LayoutByCompany="False" ShowAllDomains="False" TotalDomain="True" DefaultDates="2" />:~:LytHyc:~:ssmt-mfrs-cor_2022-12-31.xsd#ssmt-mfrs_StatementOnSubclassificationOfAssetsLiabilitiesAndEquityTable:~:False:~:True:~:ssmt-mfrs-cor_2022-12-31.xsd#ssmt-mfrs_DisclosureOnSubclassificationOfAssetsLiabilitiesAndEquityAbstract@http://www.xbrl.org/2003/role/label::ssmt-mfrs-cor_2022-12-31.xsd#ssmt-mfrs_StatementOnSubclassificationOfAssetsLiabilitiesAndEquityAbstract@http://www.xbrl.org/2003/role/label::ssmt-mfrs-cor_2022-12-31.xsd#ssmt-mfrs_StatementOnSubclassificationOfAssetsLiabilitiesAndEquityLineItems@http://www.xbrl.org/2003/role/label:~:ssmt-mfrs-cor_2022-12-31.xsd#ssmt-mfrs_StatementOnSubclassificationOfAssetsLiabilitiesAndEquityTable
C18: #LAYOUTSCSR# | D18: #PRIM# | G18: #TABLE# | H18: #LAYOUTECSR#
C19: #STDTENDTDATE# | E19: =TEXT(DATE(MID(E21,7,4),MID(E21,4,2),MID(E21,1,2)),"dd/MM/yyyy")&" - "&TEXT(DATE(MID(E22,7,4),MID(E22,4,2),MID(E22,1,2)),"dd/MM/yyyy") -> 01/01/2024 - 31/12/2024 | F19: =TEXT(DATE(MID(F21,7,4),MID(F21,4,2),MID(F21,1,2)),"dd/MM/yyyy")&" - "&TEXT(DATE(MID(F22,7,4),MID(F22,4,2),MID(F22,1,2)),"dd/MM/yyyy") -> 01/01/2023 - 31/12/2023
C20: #UNITSCALE# | E20: =StartUp!$E$8 -> MYR'000 | F20: =StartUp!$E$8 -> MYR'000
C21: #STDT# | E21: =StartUp!$D$8 -> 01/01/2024 | F21: =StartUp!$D$10 -> 01/01/2023
C22: #ENDT# | E22: =StartUp!$D$9 -> 31/12/2024 | F22: =StartUp!$D$11 -> 31/12/2023
C23: #TABLE#
A24: ssmt-mfrs-cor_2022-12-31.xsd#ssmt-mfrs_StatementOnSubclassificationOfAssetsLiabilitiesAndEquityAbstract | D24: Statement on sub-classification of assets, liabilities and equity
A25: ssmt-mfrs-cor_2022-12-31.xsd#ssmt-mfrs_StatementOnSubclassificationOfAssetsLiabilitiesAndEquityLineItems | D25: Statement on sub-classification of assets, liabilities and equity
A26: ssmt-mfrs-cor_2022-12-31.xsd#ssmt-mfrs_SubclassificationOfAssetsLiabilitiesAndEquityAbstract | D26: Sub-classification of assets, liabilities and equity
A27: full_ifrs-cor_2022-03-24.xsd#ifrs-full_PropertyPlantAndEquipmentAbstract | D27: Property, plant and equipment
A28: full_ifrs-cor_2022-03-24.xsd#ifrs-full_LandAndBuildingsAbstract | D28: Land and buildings
A29: ssmt-mfrs-cor_2022-12-31.xsd#ssmt-mfrs_LandAbstract | D29: Land
A30: ssmt-mfrs-cor_2022-12-31.xsd#ssmt-mfrs_FreeholdLand | D30: Freehold land
A31: ssmt-mfrs-cor_2022-12-31.xsd#ssmt-mfrs_LongtermLeaseholdLand | D31: Long term leasehold land
A32: ssmt-mfrs-cor_2022-12-31.xsd#ssmt-mfrs_ShorttermLeaseholdLand | D32: Short term leasehold land
A33: full_ifrs-cor_2022-03-24.xsd#ifrs-full_Land@http://www.xbrl.org/2003/role/totalLabel | D33: Total land | E33: =1*E30+1*E31+1*E32 -> 0 | F33: =1*F30+1*F31+1*F32 -> 0
A34: ssmt-mfrs-cor_2022-12-31.xsd#ssmt-mfrs_BuildingAbstract | D34: Buildings
A35: ssmt-mfrs-cor_2022-12-31.xsd#ssmt-mfrs_BuildingOnFreeholdLand | D35: Building on freehold land | E35: 1000000
A36: ssmt-mfrs-cor_2022-12-31.xsd#ssmt-mfrs_BuildingOnLongtermLeaseholdLand | D36: Building on long term leasehold land
A37: ssmt-mfrs-cor_2022-12-31.xsd#ssmt-mfrs_BuildingOnShorttermLeaseholdLand | D37: Building on short term leasehold land
A38: ssmt-mfrs-cor_2022-12-31.xsd#ssmt-mfrs_LeasedProperties | D38: Leased properties
A39: full_ifrs-cor_2022-03-24.xsd#ifrs-full_Buildings@http://xbrl.ssm.com.my/role/ssm/fs/mfrs/lab_rol_ssmt-fs-mfrs_2022-12-31/ReportingTotalLabel | D39: Total buildings | E39: =1*E35+1*E36+1*E37+1*E38 -> 1000000 | F39: =1*F35+1*F36+1*F37+1*F38 -> 0
A40: full_ifrs-cor_2022-03-24.xsd#ifrs-full_LandAndBuildings@http://www.xbrl.org/2003/role/totalLabel | D40: Total land and buildings | E40: =1*E33+1*E39 -> 1000000 | F40: =1*F33+1*F39 -> 0
A41: full_ifrs-cor_2022-03-24.xsd#ifrs-full_VehiclesAbstract | D41: Vehicles
A42: ssmt-mfrs-cor_2022-12-31.xsd#ssmt-mfrs_Vessels | D42: Vessels
A43: full_ifrs-cor_2022-03-24.xsd#ifrs-full_Aircraft | D43: Aircraft
A44: full_ifrs-cor_2022-03-24.xsd#ifrs-full_MotorVehicles | D44: Motor vehicles
A45: ssmt-mfrs-cor_2022-12-31.xsd#ssmt-mfrs_OtherVehicles | D45: Other vehicles
A46: full_ifrs-cor_2022-03-24.xsd#ifrs-full_Vehicles@http://www.xbrl.org/2003/role/totalLabel | D46: Total vehicles | E46: =1*E42+1*E43+1*E44+1*E45 -> 0 | F46: =1*F42+1*F43+1*F44+1*F45 -> 0
A47: full_ifrs-cor_2022-03-24.xsd#ifrs-full_Machinery | D47: Machinery
...

Sheet SOPL-Function
A1: e626cc5a-923a-4892-95e5-46c3f6ce1818:~:AtleastOneValueInAnyLayout:~:True:~:<?xml version="1.0" encoding="utf-16"?>_x000D_ <Customization xmlns:xsi="http://www.w3.org/2001/XMLSchema-instance" xmlns:xsd="http://www.w3.org/2001/XMLSchema" ComparitiveDate="False" LayoutByDate="False" LayoutByCompany="False" ShowAllDomains="False" TotalDomain="True" DefaultDates="2" />:~:http://xbrl.ssm.com.my/role/ssm/rol_ssmt-fs-mfrs_2022-12-31/ssmt-fs-mfrs_2022-12-31_role-300100x:~:None
D2: FS-MFRS Statement of profit or loss, by function of expense
D3: * denotes mandatory items to be reported
C5: 51d9dbc9-4f1f-49fa-bd4a-66bd69bffe70:~:SOPL-Function_1_TBLYT:~:NotMandatory:~:False:~:0:~:True:~:<?xml version="1.0" encoding="utf-16"?>_x000D_ <Customization xmlns:xsi="http://www.w3.org/2001/XMLSchema-instance" xmlns:xsd="http://www.w3.org/2001/XMLSchema" ComparitiveDate="False" LayoutByDate="False" LayoutByCompany="False" ShowAllDomains="False" TotalDomain="True" DefaultDates="2" />:~:LytTxb:~::~:False:~:True:~:ssmt-cor_2022-12-31.xsd#ssmt_DisclosureOnStatementOfProfitOrLossAbstract@http://www.xbrl.org/2003/role/label:~:
C8: #LAYOUTSCSR# | D8: #PRIM# | F8: #TABLE# | G8: #LAYOUTECSR#
C9: #TABLE#
A10: ssmt-cor_2022-12-31.xsd#ssmt_DisclosureOnStatementOfProfitOrLossAbstract | D10: Disclosure on statement of profit or loss
C11: #TABLE#
C12: #LAYOUTSCER# | G12: #LAYOUTECER#
C15: 1dd880d0-8b74-4382-a51d-a00d3dbba064:~:SOPL-Function_2:~:NotMandatory:~:True:~:1:~:True:~:<?xml version="1.0" encoding="utf-16"?>_x000D_ <Customization xmlns:xsi="http://www.w3.org/2001/XMLSchema-instance" xmlns:xsd="http://www.w3.org/2001/XMLSchema" ComparitiveDate="False" LayoutByDate="False" LayoutByCompany="False" ShowAllDomains="False" TotalDomain="True" DefaultDates="2" />:~:LytHyc:~:ssmt-cor_2022-12-31.xsd#ssmt_StatementOfProfitOrLossTable:~:False:~:True:~:ssmt-cor_2022-12-31.xsd#ssmt_DisclosureOnStatementOfProfitOrLossAbstract@http://www.xbrl.org/2003/role/label::ssmt-cor_2022-12-31.xsd#ssmt_StatementOfProfitOrLossAbstract@http://www.xbrl.org/2003/role/label::ssmt-cor_2022-12-31.xsd#ssmt_StatementOfProfitOrLossLineItems@http://www.xbrl.org/2003/role/label:~:ssmt-cor_2022-12-31.xsd#ssmt_StatementOfProfitOrLossTable
C18: #LAYOUTSCSR# | D18: #PRIM# | G18: #TABLE# | H18: #LAYOUTECSR#
C19: #STDTENDTDATE# | E19: =TEXT(DATE(MID(E21,7,4),MID(E21,4,2),MID(E21,1,2)),"dd/MM/yyyy")&" - "&TEXT(DATE(MID(E22,7,4),MID(E22,4,2),MID(E22,1,2)),"dd/MM/yyyy") -> 01/01/2024 - 31/12/2024 | F19: =TEXT(DATE(MID(F21,7,4),MID(F21,4,2),MID(F21,1,2)),"dd/MM/yyyy")&" - "&TEXT(DATE(MID(F22,7,4),MID(F22,4,2),MID(F22,1,2)),"dd/MM/yyyy") -> 01/01/2023 - 31/12/2023
C20: #UNITSCALE# | E20: =StartUp!$E$8 -> MYR'000 | F20: =StartUp!$E$8 -> MYR'000
C21: #STDT# | E21: =StartUp!$D$8 -> 01/01/2024 | F21: =StartUp!$D$10 -> 01/01/2023
C22: #ENDT# | E22: =StartUp!$D$9 -> 31/12/2024 | F22: =StartUp!$D$11 -> 31/12/2023
C23: #TABLE#
A24: ssmt-cor_2022-12-31.xsd#ssmt_StatementOfProfitOrLossAbstract | D24: Statement of Profit or Loss
A25: ssmt-cor_2022-12-31.xsd#ssmt_StatementOfProfitOrLossLineItems | D25: Statement of profit or loss
A26: ssmt-mfrs-cor_2022-12-31.xsd#ssmt-mfrs_ContinuingOperationsAbstract | D26: Continuing operations
A27: full_ifrs-cor_2022-03-24.xsd#ifrs-full_Revenue | D27: *Revenue | E27: ='SOPL-Analysis-Function'!E60 -> 0 | F27: ='SOPL-Analysis-Function'!F60 -> 0 | G27: See details
A28: full_ifrs-cor_2022-03-24.xsd#ifrs-full_CostOfSales | D28: *Cost of sales | E28: ='SOPL-Analysis-Function'!E67 -> 0 | F28: ='SOPL-Analysis-Function'!F67 -> 0 | G28: See details
A29: full_ifrs-cor_2022-03-24.xsd#ifrs-full_GrossProfit@http://www.xbrl.org/2009/role/netLabel | D29: *Gross profit | E29: =1*E27+-1*E28 -> 0 | F29: =1*F27+-1*F28 -> 0
A30: full_ifrs-cor_2022-03-24.xsd#ifrs-full_OtherIncome | D30: *Other income | E30: ='SOPL-Analysis-Function'!E110 -> 0 | F30: ='SOPL-Analysis-Function'!F110 -> 0 | G30: See details
A31: ssmt-mfrs-cor_2022-12-31.xsd#ssmt-mfrs_SellingAndDistributionExpenses | D31: Selling and distribution expenses
A32: full_ifrs-cor_2022-03-24.xsd#ifrs-full_AdministrativeExpense | D32: *Administrative expenses
A33: full_ifrs-cor_2022-03-24.xsd#ifrs-full_ResearchAndDevelopmentExpense | D33: Research and development expense
A34: full_ifrs-cor_2022-03-24.xsd#ifrs-full_OtherExpenseByFunction@http://xbrl.ssm.com.my/role/ssm/lab_rol_ssmt-fs-mfrs_2022-12-31/ReportingLabel | D34: *Other expenses | E34: ='SOPL-Analysis-Function'!E154 -> 0 | F34: ='SOPL-Analysis-Function'!F154 -> 0 | G34: See details
A35: full_ifrs-cor_2022-03-24.xsd#ifrs-full_ProfitLossFromOperatingActivities@http://www.xbrl.org/2003/role/totalLabel | D35: Profit (loss) from operating activities | E35: =1*E27+-1*E28+1*E30+-1*E31+-1*E32+-1*E33+-1*E34 -> 0 | F35: =1*F27+-1*F28+1*F30+-1*F31+-1*F32+-1*F33+-1*F34 -> 0
A36: full_ifrs-cor_2022-03-24.xsd#ifrs-full_FinanceIncome | D36: *Finance income | E36: ='SOPL-Analysis-Function'!E158 -> 0 | F36: ='SOPL-Analysis-Function'!F158 -> 0 | G36: See details
A37: full_ifrs-cor_2022-03-24.xsd#ifrs-full_FinanceCosts | D37: *Finance costs
A38: full_ifrs-cor_2022-03-24.xsd#ifrs-full_ShareOfProfitLossOfAssociatesAndJointVenturesAccountedForUsingEquityMethod | D38: Share of profit (loss) of associates and joint ventures accounted for using equity method
A39: ssmt-mfrs-cor_2022-12-31.xsd#ssmt-mfrs_FairValuationGainLossArisingFromDistributionOfNoncashAssetsToOwners | D39: Fair valuation gain (loss) arising from distribution of non-cash assets to owners
A40: full_ifrs-cor_2022-03-24.xsd#ifrs-full_ProfitLossBeforeTax@http://www.xbrl.org/2003/role/totalLabel | D40: *Profit (loss) before tax | E40: =1*E27+-1*E28+1*E30+-1*E31+-1*E32+-1*E33+-1*E34+1*E36+-1*E37+1*E38+1*E39 -> 0 | F40: =1*F27+-1*F28+1*F30+-1*F31+-1*F32+-1*F33+-1*F34+1*F36+-1*F37+1*F38+1*F39 -> 0
A41: full_ifrs-cor_2022-03-24.xsd#ifrs-full_IncomeTaxExpenseContinuingOperations@http://xbrl.ssm.com.my/role/ssm/lab_rol_ssmt-fs-mfrs_2022-12-31/ReportingLabel | D41: *Tax expense
A42: ssmt-mfrs-cor_2022-12-31.xsd#ssmt-mfrs_ContributionOfZakat | D42: Contribution of zakat
A43: full_ifrs-cor_2022-03-24.xsd#ifrs-full_ProfitLossFromContinuingOperations@http://www.xbrl.org/2003/role/totalLabel | D43: *Profit (loss) from continuing operations | E43: =1*E40+-1*E41+-1*E42 -> 0 | F43: =1*F40+-1*F41+-1*F42 -> 0
A44: ssmt-mfrs-cor_2022-12-31.xsd#ssmt-mfrs_DiscontinuedOperationsAbstract | D44: Discontinued operations
A45: full_ifrs-cor_2022-03-24.xsd#ifrs-full_ProfitLossFromDiscontinuedOperations@http://xbrl.ssm.com.my/role/ssm/lab_rol_ssmt-fs-mfrs_2022-12-31/ReportingLabel | D45: Profit (loss) from discontinued operations, net of tax
A46: full_ifrs-cor_2022-03-24.xsd#ifrs-full_ProfitLoss@http://www.xbrl.org/2003/role/totalLabel | D46: *Profit (loss) | E46: =1*E43+1*E45 -> 0 | F46: =1*F43+1*F45 -> 0 | G46: See details
A47: full_ifrs-cor_2022-03-24.xsd#ifrs-full_ProfitLossAttributableToAbstract | D47: Profit (loss), attributable to
...

Sheet SOPL-Analysis-Function
A1: eadafe3e-14c4-402f-a1ac-c5a41983981f:~:AtleastOneValueInAnyLayout:~:True:~:<?xml version="1.0" encoding="utf-16"?>_x000D_ <Customization xmlns:xsi="http://www.w3.org/2001/XMLSchema-instance" xmlns:xsd="http://www.w3.org/2001/XMLSchema" ComparitiveDate="False" LayoutByDate="False" LayoutByCompany="False" ShowAllDomains="False" TotalDomain="True" DefaultDates="2" />:~:http://xbrl.ssm.com.my/role/ssm/rol_ssmt-fs-mfrs_2022-12-31/ssmt-fs-mfrs_2022-12-31_role-300200x:~:None
D2: FS-MFRS Analysis of profit or loss, by function of expense
D3: * denotes mandatory items to be reported
C5: d9ddaf2b-8017-4ca0-abda-c2a797dc7ff4:~:SOPL-Analysis-Function_1_TBLYT:~:NotMandatory:~:False:~:0:~:True:~:<?xml version="1.0" encoding="utf-16"?>_x000D_ <Customization xmlns:xsi="http://www.w3.org/2001/XMLSchema-instance" xmlns:xsd="http://www.w3.org/2001/XMLSchema" ComparitiveDate="False" LayoutByDate="False" LayoutByCompany="False" ShowAllDomains="False" TotalDomain="True" DefaultDates="2" />:~:LytTxb:~::~:False:~:True:~:ssmt-mfrs-cor_2022-12-31.xsd#ssmt-mfrs_DisclosureOnStatementOfProfitOrLossAbstract@http://www.xbrl.org/2003/role/label:~:
C8: #LAYOUTSCSR# | D8: #PRIM# | F8: #TABLE# | G8: #LAYOUTECSR#
C9: #TABLE#
A10: ssmt-mfrs-cor_2022-12-31.xsd#ssmt-mfrs_DisclosureOnStatementOfProfitOrLossAbstract | D10: Disclosure on statement of profit or loss
C11: #TABLE#
C12: #LAYOUTSCER# | G12: #LAYOUTECER#
C15: b359ba42-7d42-49c8-a7b7-2e491646c7b4:~:SOPL-Analysis-Function_2:~:NotMandatory:~:True:~:1:~:True:~:<?xml version="1.0" encoding="utf-16"?>_x000D_ <Customization xmlns:xsi="http://www.w3.org/2001/XMLSchema-instance" xmlns:xsd="http://www.w3.org/2001/XMLSchema" ComparitiveDate="False" LayoutByDate="False" LayoutByCompany="False" ShowAllDomains="False" TotalDomain="True" DefaultDates="2" />:~:LytHyc:~:ssmt-mfrs-cor_2022-12-31.xsd#ssmt-mfrs_StatementOfProfitOrLossTable:~:False:~:True:~:ssmt-mfrs-cor_2022-12-31.xsd#ssmt-mfrs_DisclosureOnStatementOfProfitOrLossAbstract@http://www.xbrl.org/2003/role/label::ssmt-mfrs-cor_2022-12-31.xsd#ssmt-mfrs_AnalysisOfProfitOrLossAbstract@http://www.xbrl.org/2003/role/label::ssmt-mfrs-cor_2022-12-31.xsd#ssmt-mfrs_StatementOfProfitOrLossLineItems@http://www.xbrl.org/2003/role/label:~:ssmt-mfrs-cor_2022-12-31.xsd#ssmt-mfrs_StatementOfProfitOrLossTable
C18: #LAYOUTSCSR# | D18: #PRIM# | G18: #TABLE# | H18: #LAYOUTECSR#
C19: #STDTENDTDATE# | E19: =TEXT(DATE(MID(E21,7,4),MID(E21,4,2),MID(E21,1,2)),"dd/MM/yyyy")&" - "&TEXT(DATE(MID(E22,7,4),MID(E22,4,2),MID(E22,1,2)),"dd/MM/yyyy") -> 01/01/2024 - 31/12/2024 | F19: =TEXT(DATE(MID(F21,7,4),MID(F21,4,2),MID(F21,1,2)),"dd/MM/yyyy")&" - "&TEXT(DATE(MID(F22,7,4),MID(F22,4,2),MID(F22,1,2)),"dd/MM/yyyy") -> 01/01/2023 - 31/12/2023
C20: #UNITSCALE# | E20: =StartUp!$E$8 -> MYR'000 | F20: =StartUp!$E$8 -> MYR'000
C21: #STDT# | E21: =StartUp!$D$8 -> 01/01/2024 | F21: =StartUp!$D$10 -> 01/01/2023
C22: #ENDT# | E22: =StartUp!$D$9 -> 31/12/2024 | F22: =StartUp!$D$11 -> 31/12/2023
C23: #TABLE#
A24: ssmt-mfrs-cor_2022-12-31.xsd#ssmt-mfrs_AnalysisOfProfitOrLossAbstract | D24: Analysis of profit or loss
A25: ssmt-mfrs-cor_2022-12-31.xsd#ssmt-mfrs_StatementOfProfitOrLossLineItems | D25: Statement of profit or loss
A26: full_ifrs-cor_2022-03-24.xsd#ifrs-full_RevenueAbstract | D26: Revenue
A27: ssmt-mfrs-cor_2022-12-31.xsd#ssmt-mfrs_RevenueFromSaleOfGoodsAbstract | D27: Revenue from sale of goods
A28: full_ifrs-cor_2022-03-24.xsd#ifrs-full_RevenueFromSaleOfTelecommunicationEquipment@http://xbrl.ssm.com.my/role/ssm/lab_rol_ssmt-fs-mfrs_2022-12-31/ReportingLabel | D28: Revenue from sale of broadband and telecommunication
A29: ssmt-mfrs-cor_2022-12-31.xsd#ssmt-mfrs_RevenueFromSaleOfProperty@http://xbrl.ssm.com.my/role/ssm/lab_rol_ssmt-fs-mfrs_2022-12-31/ReportingLabel | D29: Revenue from property development
A30: ssmt-mfrs-cor_2022-12-31.xsd#ssmt-mfrs_RevenueFromSaleOfConstructionContracts@http://xbrl.ssm.com.my/role/ssm/lab_rol_ssmt-fs-mfrs_2022-12-31/ReportingLabel | D30: Revenue from construction contracts
A31: ssmt-mfrs-cor_2022-12-31.xsd#ssmt-mfrs_RevenueFromSaleOfCleanWaterTreatmentAndDisposalOfWasteWater@http://xbrl.ssm.com.my/role/ssm/lab_rol_ssmt-fs-mfrs_2022-12-31/ReportingLabel | D31: Revenue from clean water, treatment and disposal of waste water
A32: full_ifrs-cor_2022-03-24.xsd#ifrs-full_RevenueFromSaleOfFoodAndBeverage | D32: Revenue from sale of food and beverage
A33: full_ifrs-cor_2022-03-24.xsd#ifrs-full_RevenueFromSaleOfAgriculturalProduce | D33: Revenue from sale of agricultural produce
A34: full_ifrs-cor_2022-03-24.xsd#ifrs-full_RevenueFromSaleOfOilAndGasProducts | D34: Revenue from sale of oil and gas products
A35: ssmt-mfrs-cor_2022-12-31.xsd#ssmt-mfrs_RevenueFromSaleOfOtherGoods | D35: Revenue from sale of other goods
A36: full_ifrs-cor_2022-03-24.xsd#ifrs-full_RevenueFromSaleOfGoods@http://xbrl.ssm.com.my/role/ssm/fs/mfrs/lab_rol_ssmt-fs-mfrs_2022-12-31/ReportingTotalLabel | D36: Total revenue from sale of goods | E36: =1*E28+1*E29+1*E30+1*E31+1*E32+1*E33+1*E34+1*E35 -> 0 | F36: =1*F28+1*F29+1*F30+1*F31+1*F32+1*F33+1*F34+1*F35 -> 0
A37: ssmt-mfrs-cor_2022-12-31.xsd#ssmt-mfrs_RevenueFromRenderingOfServicesAbstract | D37: Revenue from rendering of services
A38: ssmt-mfrs-cor_2022-12-31.xsd#ssmt-mfrs_RevenueFromEntertainmentOperations | D38: Revenue from rendering of entertainment services
A39: full_ifrs-cor_2022-03-24.xsd#ifrs-full_RevenueFromRenderingOfTelecommunicationServices | D39: Revenue from rendering of telecommunication services
A40: full_ifrs-cor_2022-03-24.xsd#ifrs-full_RevenueFromRenderingOfTransportServices | D40: Revenue from rendering of transport services
A41: full_ifrs-cor_2022-03-24.xsd#ifrs-full_RevenueFromRenderingOfInformationTechnologyServices | D41: Revenue from rendering of information technology services
A42: ssmt-mfrs-cor_2022-12-31.xsd#ssmt-mfrs_RevenueFromEducationalServices | D42: Revenue from rendering of educational services
A43: ssmt-mfrs-cor_2022-12-31.xsd#ssmt-mfrs_RevenueFromHealthcareServices | D43: Revenue from rendering of healthcare services
A44: full_ifrs-cor_2022-03-24.xsd#ifrs-full_RevenueFromRenderingOfCargoAndMailTransportServices@http://xbrl.ssm.com.my/role/ssm/lab_rol_ssmt-fs-mfrs_2022-12-31/ReportingLabel | D44: Revenue from rendering of shipping and shipping related services
A45: ssmt-mfrs-cor_2022-12-31.xsd#ssmt-mfrs_RevenueFromRenderingOfOtherServices | D45: Revenue from rendering of other services
A46: full_ifrs-cor_2022-03-24.xsd#ifrs-full_RevenueFromRenderingOfServices@http://xbrl.ssm.com.my/role/ssm/fs/mfrs/lab_rol_ssmt-fs-mfrs_2022-12-31/ReportingTotalLabel | D46: Total revenue from rendering of services | E46: =1*E38+1*E39+1*E40+1*E41+1*E42+1*E43+1*E44+1*E45 -> 0 | F46: =1*F38+1*F39+1*F40+1*F41+1*F42+1*F43+1*F44+1*F45 -> 0
A47: ssmt-mfrs-cor_2022-12-31.xsd#ssmt-mfrs_InterestIncomeAbstract | D47: Interest income
...

Sheet SOCI-BeforeOfTax
A1: 05e58da4-b2cb-4591-bf01-0861836ec42b:~:AtleastOneValueInAnyLayout:~:True:~:<?xml version="1.0" encoding="utf-16"?>_x000D_ <Customization xmlns:xsi="http://www.w3.org/2001/XMLSchema-instance" xmlns:xsd="http://www.w3.org/2001/XMLSchema" ComparitiveDate="False" LayoutByDate="False" LayoutByCompany="False" ShowAllDomains="False" TotalDomain="True" DefaultDates="2" />:~:http://xbrl.ssm.com.my/role/ssm/rol_ssmt-fs-mfrs_2022-12-31/ssmt-fs-mfrs_2022-12-31_role-400100y:~:None
D2: FS-MFRS Statement of Comprehensive Income - Before tax
D3: * denotes mandatory items to be reported
