Workbook

Sheet SOFP-OrdOfLiq
B1: 01/01/YYYY - 31/12/YYYY | C1: 01/01/YYYY - 31/12/YYYY | D1: Source
A3: Statement of financial position, order of liquidity
A4: Statement of financial position [abstract]
A5: Statement of financial position [line items]
A6: Assets [abstract]
A7: Total property, plant and equipment | B7: ='SOFP-Sub-OrdOfLiq'!B38 | C7: ='SOFP-Sub-OrdOfLiq'!C38
A8: Total investment property | B8: ='SOFP-Sub-OrdOfLiq'!B48 | C8: ='SOFP-Sub-OrdOfLiq'!C48
A9: Biological assets | B9: ='SOFP-Sub-OrdOfLiq'!B52 | C9: ='SOFP-Sub-OrdOfLiq'!C52
A10: Right-of-use assets
A11: Service concession assets
A12: Total intangible assets and goodwill | B12: ='SOFP-Sub-OrdOfLiq'!B68 | C12: ='SOFP-Sub-OrdOfLiq'!C68
A13: Investments in subsidiaries reported in separate financial statements | B13: ='SOFP-Sub-OrdOfLiq'!B76 | C13: ='SOFP-Sub-OrdOfLiq'!C76
A14: Investments in associates reported in separate financial statements | B14: ='SOFP-Sub-OrdOfLiq'!B85 | C14: ='SOFP-Sub-OrdOfLiq'!C85
A15: Investments in joint ventures reported in separate financial statements | B15: ='SOFP-Sub-OrdOfLiq'!B94 | C15: ='SOFP-Sub-OrdOfLiq'!C94
A16: Investments other than investments accounted for using equity method
A17: Current tax assets
A18: Total trade and other receivables | B18: ='SOFP-Sub-OrdOfLiq'!B127 | C18: ='SOFP-Sub-OrdOfLiq'!C127
A19: Total contract assets
A20: Deferred tax assets
A21: Inventories | B21: ='SOFP-Sub-OrdOfLiq'!B134 | C21: ='SOFP-Sub-OrdOfLiq'!C134
A22: Derivative financial assets | B22: ='SOFP-Sub-OrdOfLiq'!B143 | C22: ='SOFP-Sub-OrdOfLiq'!C143
A23: Total Cash and bank balances | B23: ='SOFP-Sub-OrdOfLiq'!B158 | C23: ='SOFP-Sub-OrdOfLiq'!C158
A24: Other assets | B24: ='SOFP-Sub-OrdOfLiq'!B163 | C24: ='SOFP-Sub-OrdOfLiq'!C163
A25: Assets other than assets held for sale | B25: =1*B7+1*B8+1*B9+1*B10+1*B11+1*B12+1*B13+1*B14+1*B15+1*B16+1*B17+1*B18+1*B19+1*B20+1*B21+1*B22+1*B23+1*B24 | C25: =1*C7+1*C8+1*C9+1*C10+1*C11+1*C12+1*C13+1*C14+1*C15+1*C16+1*C17+1*C18+1*C19+1*C20+1*C21+1*C22+1*C23+1*C24
A26: Total non-current assets or disposal groups classified as held for sale or as held for distribution to owners
A27: Total assets | B27: =1*B7+1*B8+1*B9+1*B10+1*B11+1*B12+1*B13+1*B14+1*B15+1*B16+1*B17+1*B18+1*B19+1*B20+1*B21+1*B22+1*B23+1*B24+1*B26 | C27: =1*C7+1*C8+1*C9+1*C10+1*C11+1*C12+1*C13+1*C14+1*C15+1*C16+1*C17+1*C18+1*C19+1*C20+1*C21+1*C22+1*C23+1*C24+1*C26
A28: Equity and liabilities [abstract]
A29: Equity [abstract]
A30: Total issued capital | B30: ='SOFP-Sub-OrdOfLiq'!B168 | C30: ='SOFP-Sub-OrdOfLiq'!C168
A31: Total retained earnings
A32: Treasury shares
A33: Total other reserves | B33: ='SOFP-Sub-OrdOfLiq'!B187 | C33: ='SOFP-Sub-OrdOfLiq'!C187
A34: Total equity attributable to owners of parent | B34: =1*B30+1*B31+-1*B32+1*B33 | C34: =1*C30+1*C31+-1*C32+1*C33
A35: Equity, others components | B35: ='SOFP-Sub-OrdOfLiq'!B194 | C35: ='SOFP-Sub-OrdOfLiq'!C194
A36: Non-controlling interests
A37: Total equity | B37: =1*B30+1*B31+-1*B32+1*B33+1*B35+1*B36 | C37: =1*C30+1*C31+-1*C32+1*C33+1*C35+1*C36
A38: Liabilities [abstract]
A39: Service concession liabilities
A40: Total borrowings | B40: ='SOFP-Sub-OrdOfLiq'!B241 | C40: ='SOFP-Sub-OrdOfLiq'!C241
A41: Total lease liabilities
...

Sheet SOFP-Sub-OrdOfLiq
B1: 01/01/YYYY - 31/12/YYYY | C1: 01/01/YYYY - 31/12/YYYY | D1: Source
A3: Sub-classification, order of liquidity
A4: Statement on sub-classification of assets, liabilities and equity [abstract]
A5: Statement on sub-classification of assets, liabilities and equity [line items]
A6: Property, plant and equipment [abstract]
A7: Land and buildings [abstract]
A8: Land [abstract]
A9: Freehold land
A10: Long term leasehold land
A11: Short term leasehold land
A12: Land | B12: =1*B9+1*B10+1*B11 | C12: =1*C9+1*C10+1*C11
A13: Buildings [abstract]
A14: Building on freehold land
A15: Building on long term leasehold land
A16: Building on short term leasehold land
A17: Leased properties
A18: Buildings | B18: =1*B14+1*B15+1*B16+1*B17 | C18: =1*C14+1*C15+1*C16+1*C17
A19: Total land and buildings | B19: =1*B12+1*B18 | C19: =1*C12+1*C18
A20: Vehicles [abstract]
A21: Vessels
A22: Aircraft
A23: Motor vehicles
A24: Other vehicles
A25: Total vehicles | B25: =1*B21+1*B22+1*B23+1*B24 | C25: =1*C21+1*C22+1*C23+1*C24
A26: Machinery
A27: Plant and equipment
A28: Office equipment, fixture and fittings
A29: Computer software and hardware
A30: Bearer plants
A31: Infrastructure and site facilities
A32: Mining assets
A33: Oil and gas assets
A34: Tangible exploration and evaluation assets
A35: Telecommunication equipments
A36: Construction in progress
A37: Other property, plant and equipment
A38: Total property, plant and equipment | B38: =1*B19+1*B25+1*B26+1*B27+1*B28+1*B29+1*B30+1*B31+1*B32+1*B33+1*B34+1*B35+1*B36+1*B37 | C38: =1*C19+1*C25+1*C26+1*C27+1*C28+1*C29+1*C30+1*C31+1*C32+1*C33+1*C34+1*C35+1*C36+1*C37
A39: Investment property [abstract]
A40: Investment properties completed, at fair value [abstract]
A41: Freehold land and building
...
