Workbook

Sheet SOPL-Nature
B1: 01/01/YYYY - 31/12/YYYY | C1: 01/01/YYYY - 31/12/YYYY | D1: Source
A3: Statement of profit or loss, by nature of expense
A4: Statement of Profit or Loss [abstract]
A5: Statement of profit or loss [line items]
A6: Continuing operations [abstract]
A7: Total revenue | B7: ='SOPL-Analysis-Nature'!B40 | C7: ='SOPL-Analysis-Nature'!C40
A8: Other income | B8: ='SOPL-Analysis-Nature'!B83 | C8: ='SOPL-Analysis-Nature'!C83
A9: Decrease (increase) in inventories of finished goods and work in progress
A10: Other work performed by entity and capitalised
A11: Raw materials and consumables used
A12: Total depreciation, amortisation and impairment loss (reversal of impairment loss) recognised in profit or loss
A13: Total employee benefits expense, by nature | B13: ='SOPL-Analysis-Nature'!B95 | C13: ='SOPL-Analysis-Nature'!C95
A14: Other expenses, by nature | B14: ='SOPL-Analysis-Nature'!B128 | C14: ='SOPL-Analysis-Nature'!C128
A15: Profit (loss) from operating activities | B15: =1*B7+1*B8+-1*B9+1*B10+-1*B11+-1*B12+-1*B13+-1*B14 | C15: =1*C7+1*C8+-1*C9+1*C10+-1*C11+-1*C12+-1*C13+-1*C14
A16: Finance income | B16: ='SOPL-Analysis-Nature'!B132 | C16: ='SOPL-Analysis-Nature'!C132
A17: Finance costs
A18: Total share of profit (loss) of associates and joint ventures accounted for using equity method
A19: Profit (loss) before tax | B19: =1*B7+1*B8+-1*B9+1*B10+-1*B11+-1*B12+-1*B13+-1*B14+1*B16+-1*B17+1*B18 | C19: =1*C7+1*C8+-1*C9+1*C10+-1*C11+-1*C12+-1*C13+-1*C14+1*C16+-1*C17+1*C18
A20: Total tax expense (income)
A21: Contribution of zakat
A22: Profit (loss) from continuing operations | B22: =1*B19+-1*B20+-1*B21 | C22: =1*C19+-1*C20+-1*C21
A23: Discontinued operations [abstract]
A24: Profit (loss) from discontinued operations
A25: Profit (loss) | B25: =1*B22+1*B24 | C25: =1*C22+1*C24
A26: Profit (loss), attributable to [abstract]
A27: Profit (loss), attributable to owners of parent
A28: Profit (loss) attributable to equity other components
A29: Profit (loss), attributable to non-controlling interests
A30: Profit (loss) | B30: =1*B27+1*B28+1*B29 | C30: =1*C27+1*C28+1*C29
A31: Earnings per share [abstract]
A32: Basic earnings per share [abstract]
A33: Basic earnings (loss) per share from continuing operations
A34: Basic earnings (loss) per share from discontinued operations
A35: Total basic earnings (loss) per share | B35: =1*B33+1*B34 | C35: =1*C33+1*C34
A36: Diluted earnings per share [abstract]
A37: Diluted earnings (loss) per share from continuing operations
A38: Diluted earnings (loss) per share from discontinued operations
A39: Total diluted earnings (loss) per share | B39: =1*B37+1*B38 | C39: =1*C37+1*C38

Sheet SOPL-Analysis-Nature
B1: 01/01/YYYY - 31/12/YYYY | C1: 01/01/YYYY - 31/12/YYYY | D1: Source
A3: Analysis of profit or loss, by nature of expense
A4: Analysis of profit or loss [abstract]
A5: Statement of profit or loss [line items]
A6: Revenue [abstract]
A7: Revenue from sale of goods [abstract]
A8: Revenue from sale of telecommunication equipment
A9: Revenue from sale of property
A10: Revenue from sale of construction contracts
A11: Revenue from sale of clean water, treatment and disposal of waste water
A12: Revenue from sale of food and beverage
A13: Revenue from sale of agricultural produce
A14: Revenue from sale of oil and gas products
A15: Revenue from sale of other goods
A16: Revenue from sale of goods | B16: =1*B8+1*B9+1*B10+1*B11+1*B12+1*B13+1*B14+1*B15 | C16: =1*C8+1*C9+1*C10+1*C11+1*C12+1*C13+1*C14+1*C15
A17: Revenue from rendering of services [abstract]
A18: Revenue from rendering of entertainment services
A19: Total revenue from rendering of telecommunication services
A20: Revenue from rendering of transport services
A21: Revenue from rendering of information technology services
A22: Revenue from rendering of educational services
A23: Revenue from rendering of healthcare services
A24: Revenue from rendering of cargo and mail transport services
A25: Revenue from rendering of other services
A26: Revenue from rendering of services | B26: =1*B18+1*B19+1*B20+1*B21+1*B22+1*B23+1*B24+1*B25 | C26: =1*C18+1*C19+1*C20+1*C21+1*C22+1*C23+1*C24+1*C25
A27: Interest income [abstract]
A28: Interest income on loans and receivables
A29: Interest income on other financial assets
A30: Interest income | B30: =1*B28+1*B29 | C30: =1*C28+1*C29
A31: Fee and commission income [abstract]
A32: Brokerage fee income
A33: Portfolio and other management fee income
A34: Other fee and commission income
A35: Total fee and commission income | B35: =1*B32+1*B33+1*B34 | C35: =1*C32+1*C33+1*C34
A36: Dividend income
A37: Rental income
A38: Royalty income
A39: Other revenue
A40: Total revenue | B40: =1*B16+1*B26+1*B30+1*B35+1*B36+1*B37+1*B38+1*B39 | C40: =1*C16+1*C26+1*C30+1*C35+1*C36+1*C37+1*C38+1*C39
A41: Other income [abstract]
...
