Workbook

Sheet SOFP-CuNonCu
B1: 01/01/YYYY - 31/12/YYYY | C1: 01/01/YYYY - 31/12/YYYY | D1: Source
A3: Disclosure on statement of financial position
A4: Statement of financial position
A5: Assets
A6: Non-current assets
A7: Property, plant and equipment | B7: ='SOFP-Sub-CuNonCu'!B26 | C7: ='SOFP-Sub-CuNonCu'!C26
A8: Investment properties | B8: ='SOFP-Sub-CuNonCu'!B36 | C8: ='SOFP-Sub-CuNonCu'!C36
A9: Right-of-use assets
A10: Intangible assets | B10: ='SOFP-Sub-CuNonCu'!B44 | C10: ='SOFP-Sub-CuNonCu'!C44
A11: Investment in subsidiaries | B11: ='SOFP-Sub-CuNonCu'!B49 | C11: ='SOFP-Sub-CuNonCu'!C49
A12: Investments in associates | B12: ='SOFP-Sub-CuNonCu'!B55 | C12: ='SOFP-Sub-CuNonCu'!C55
A13: Investments in joint ventures | B13: ='SOFP-Sub-CuNonCu'!B62 | C13: ='SOFP-Sub-CuNonCu'!C62
A14: Other investments
A15: Trade and other non-current receivables | B15: ='SOFP-Sub-CuNonCu'!B80 | C15: ='SOFP-Sub-CuNonCu'!C80
A16: Contract assets
A17: Deferred tax assets
A18: Other non-current assets | B18: ='SOFP-Sub-CuNonCu'!B85 | C18: ='SOFP-Sub-CuNonCu'!C85
A19: *Total non-current assets | B19: =1*B7+1*B8+1*B9+1*B10+1*B11+1*B12+1*B13+1*B14+1*B15+1*B16+1*B17+1*B18 | C19: =1*C7+1*C8+1*C9+1*C10+1*C11+1*C12+1*C13+1*C14+1*C15+1*C16+1*C17+1*C18
A20: Current assets
A21: Inventories | B21: ='SOFP-Sub-CuNonCu'!B92 | C21: ='SOFP-Sub-CuNonCu'!C92
A22: Other investments
A23: Current tax assets
A24: Trade and other current receivables | B24: ='SOFP-Sub-CuNonCu'!B117 | C24: ='SOFP-Sub-CuNonCu'!C117
A25: Contract assets
A26: Cash and cash equivalents | B26: ='SOFP-Sub-CuNonCu'!B131 | C26: ='SOFP-Sub-CuNonCu'!C131
A27: Other current assets
A28: Total current assets other than assets held for sale
A29: Assets or disposal group classified as held for sale or as held for distribution to owners
A30: *Total current assets | B30: =1*B21+1*B22+1*B23+1*B24+1*B25+1*B26+1*B27+1*B28+1*B29 | C30: =1*C21+1*C22+1*C23+1*C24+1*C25+1*C26+1*C27+1*C28+1*C29
A31: *Total assets | B31: =1*B19+1*B30 | C31: =1*C19+1*C30
A32: Fund/Equity and Liabilities
A33: Fund/Equity and reserves
A34: Accumulated funds (deficit)
A35: Contribution from members
A36: Reserves | B36: ='SOFP-Sub-CuNonCu'!B143 | C36: ='SOFP-Sub-CuNonCu'!C143
A37: *Total fund/equity and reserves attributable to owners | B37: =1*B34+1*B35+1*B36 | C37: =1*C34+1*C35+1*C36
A38: Non-controlling interests
A39: *Total fund/equity and reserve | B39: =1*B37+1*B38 | C39: =1*C37+1*C38
A40: Liabilities
A41: Non-current liabilities
...

Sheet SOFP-Sub-CuNonCu
B1: 01/01/YYYY - 31/12/YYYY | C1: 01/01/YYYY - 31/12/YYYY | D1: Source
A3: Disclosure on sub-classification of assets, liabilities and equity
A4: Statement on sub-classification of assets, liabilities and equity
A5: Sub-classification of assets, liabilities and equity
A6: Property, plant and equipment
A7: Land and buildings
A8: Land
A9: Freehold land
A10: Long term leasehold land
A11: Short term leasehold land
A12: *Total land | B12: =1*B9+1*B10+1*B11 | C12: =1*C9+1*C10+1*C11
A13: Buildings
A14: Building on freehold land
A15: Building on long term leasehold land
A16: Building on short term leasehold land
A17: Leased properties
A18: *Total buildings | B18: =1*B14+1*B15+1*B16+1*B17 | C18: =1*C14+1*C15+1*C16+1*C17
A19: *Total land and buildings | B19: =1*B12+1*B18 | C19: =1*C12+1*C18
A20: Vehicles
A21: Plant and equipment
A22: Office equipment, fixture and fittings
A23: Computer software and hardware
A24: Construction in progress/Asset work-in progress
A25: Other property, plant and equipment
A26: *Total property, plant and equipment | B26: =1*B19+1*B20+1*B21+1*B22+1*B23+1*B24+1*B25 | C26: =1*C19+1*C20+1*C21+1*C22+1*C23+1*C24+1*C25
A27: Investment property
A28: Investment properties completed, at carrying value
A29: Freehold land and building
A30: Leasehold land and building
A31: *Total investment properties completed, at carrying value | B31: =1*B29+1*B30 | C31: =1*C29+1*C30
A32: Investment properties under construction or development, at cost
A33: Building under construction
A34: *Total investment properties under construction or development, at cost | B34: =1*B33 | C34: =1*C33
A35: Other investment property
A36: *Total investment properties | B36: =1*B31+1*B34+1*B35 | C36: =1*C31+1*C34+1*C35
A37: Intangible assets and goodwill
A38: Intangible assets other than goodwill
A39: Copyrights, patents and other industrial property rights, service and operating rights
A40: Computer software
A41: Other intangible assets
...
