Workbook

Sheet SOIE-Nature
B1: 01/01/YYYY - 31/12/YYYY | C1: 01/01/YYYY - 31/12/YYYY | D1: Source
A3: Disclosure on statement of income and expenditure
A4: Statement of income and expenditure
A5: Continuing operations
A6: Income | B6: ='SOIE-Analysis-Nature'!B22 | C6: ='SOIE-Analysis-Nature'!C22
A7: Other income | B7: ='SOIE-Analysis-Nature'!B33 | C7: ='SOIE-Analysis-Nature'!C33
A8: Depreciation, impairment and amortisation
A9: Employee benefits expense | B9: ='SOIE-Analysis-Nature'!B41 | C9: ='SOIE-Analysis-Nature'!C41
A10: Other expenses | B10: ='SOIE-Analysis-Nature'!B77 | C10: ='SOIE-Analysis-Nature'!C77
A11: Finance income | B11: ='SOIE-Analysis-Nature'!B82 | C11: ='SOIE-Analysis-Nature'!C82
A12: Finance costs
A13: *Surplus (deficit) of income over expenditure before taxation | B13: =1*B6+1*B7+1*B11+-1*B12+-1*B8+-1*B9+-1*B10 | C13: =1*C6+1*C7+1*C11+-1*C12+-1*C8+-1*C9+-1*C10
A14: Tax expense
A15: *Total surplus (deficit) | B15: =1*B13+-1*B14 | C15: =1*C13+-1*C14
A16: Discontinued operations
A17: Surplus (deficit) from discontinued operations, net of tax
A18: *Total surplus (deficit) | B18: =1*B15+1*B17 | C18: =1*C15+1*C17
A19: Surplus (deficit), attributable to
A20: Surplus (deficit), attributable to members of company
A21: Surplus (deficit), attributable to non-controlling interests
A22: *Total surplus (deficit) | B22: =1*B20+1*B21 | C22: =1*C20+1*C21
A23: Other comprehensive income (expense), net of tax
A24: Components of other comprehensive income that will not be reclassified to profit or loss, net of tax
A25: Gains (losses) on exchange differences on translation, net of tax
A26: Other comprehensive income, net of tax, gains (losses) on revaluation
A27: Remeasurement of defined benefit liability
A28: Other comprehensive income, net of tax, gains (losses) on other items
A29: *Total other comprehensive income that will not be reclassified to profit or loss, net of tax | B29: =1*B25+1*B26+1*B27+1*B28 | C29: =1*C25+1*C26+1*C27+1*C28
A30: Components of other comprehensive income that will be reclassified to profit or loss, net of tax
A31: Gains (losses) on exchange differences on translation, net of tax
A32: Gains (losses) on cash flow hedges, net of tax
A33: Gains (losses) on hedges of net investments in foreign operations, net of tax
A34: Gains (losses) on financial assets measured at fair value through other comprehensive income, net of tax
A35: Other comprehensive income, net of tax, gains (losses) on other items
A36: *Total other comprehensive income that will be reclassified to profit or loss, net of tax | B36: =1*B31+1*B32+1*B33+1*B34+1*B35 | C36: =1*C31+1*C32+1*C33+1*C34+1*C35
A37: *Total other comprehensive surplus (deficit) | B37: =1*B29+1*B36 | C37: =1*C29+1*C36
A38: *Total comprehensive surplus (deficit) | B38: =1*B18+1*B37 | C38: =1*C18+1*C37
A39: Comprehensive surplus (deficit) attributable to
A40: Comprehensive surplus (deficit), attributable to owners
A41: Comprehensive surplus (deficit), attributable to non-controlling interests
...

Sheet SOIE-Analysis-Nature
B1: 01/01/YYYY - 31/12/YYYY | C1: 01/01/YYYY - 31/12/YYYY | D1: Source
A3: Disclosure on analysis of income and expenditure
A4: Analysis of income and expense
A5: Statement on analysis of income and expenditure
A6: Income
A7: Income from sale of goods
A8: Income from rendering of services
A9: Interest income
A10: Dividend income
A11: Rental income
A12: Income from fund raising
A13: Grant or incentives by Malaysian government or it's agencies
A14: Grant or incentives by foreign government or it's agencies
... A21: Other miscellaneous income
A22: *Total income | B22: =1*B7+1*B8+1*B9+1*B10+1*B11+1*B12+1*B13+1*B14+1*B15+1*B16+1*B17+1*B18+1*B19+1*B20+1*B21 | C22: =1*C7+1*C8+1*C9+1*C10+1*C11+1*C12+1*C13+1*C14+1*C15+1*C16+1*C17+1*C18+1*C19+1*C20+1*C21
A23: Other income
A24: Deferred income
A25: Grants or incentives
A26: Realised foreign currencies exchange gain transferred from equity
A27: Unrealised gain on foreign exchange
A28: Gain from disposal of a subsidiary, joint ventures and associates
A29: Gains on disposals of property, plant and equipment
A30: Gain on disposal from other investments
A31: Reversal of impairment loss
A32: Other miscellaneous income
A33: *Total other income | B33: =1*B24+1*B25+1*B26+1*B27+1*B28+1*B29+1*B30+1*B31+1*B32 | C33: =1*C24+1*C25+1*C26+1*C27+1*C28+1*C29+1*C30+1*C31+1*C32
A34: Employee benefits expense
A35: Wages, salaries and others
A36: Bonus
A37: Social security contributions
A38: Defined contribution plans
A39: Defined benefit plans
A40: Other employee benefit expenses
A41: *Total employee benefit expenses | B41: =1*B35+1*B36+1*B37+1*B38+1*B40+1*B39 | C41: =1*C35+1*C36+1*C37+1*C38+1*C40+1*C39
A42: Other expenses
A43: Advertisement
A44: Agent fees
A45: Assessment and quit rent
A46: Auditor's remuneration
A47: Bank charges
...
