Workbook

Sheet SOFP-CuNonCu
B1: Group | D1: Company | F1: Source
B2: 01/01/YYYY - 31/12/YYYY | C2: 01/01/YYYY - 31/12/YYYY | D2: 01/01/YYYY - 31/12/YYYY | E2: 01/01/YYYY - 31/12/YYYY
A3: Disclosure on statement of financial position
A4: Statement of financial position
A5: Assets
A6: Non-current assets
A7: Property, plant and equipment | B7: ='SOFP-Sub-CuNonCu'!B26 | C7: ='SOFP-Sub-CuNonCu'!C26 | D7: ='SOFP-Sub-CuNonCu'!D26 | E7: ='SOFP-Sub-CuNonCu'!E26
A8: Investment properties | B8: ='SOFP-Sub-CuNonCu'!B33 | C8: ='SOFP-Sub-CuNonCu'!C33 | D8: ='SOFP-Sub-CuNonCu'!D33 | E8: ='SOFP-Sub-CuNonCu'!E33
A9: Biological assets
A10: Intangible assets | B10: ='SOFP-Sub-CuNonCu'!B40 | C10: ='SOFP-Sub-CuNonCu'!C40 | D10: ='SOFP-Sub-CuNonCu'!D40 | E10: ='SOFP-Sub-CuNonCu'!E40
A11: Investments in subsidiaries | B11: ='SOFP-Sub-CuNonCu'!B46 | C11: ='SOFP-Sub-CuNonCu'!C46 | D11: ='SOFP-Sub-CuNonCu'!D46 | E11: ='SOFP-Sub-CuNonCu'!E46
A12: Investments in associates | B12: ='SOFP-Sub-CuNonCu'!B53 | C12: ='SOFP-Sub-CuNonCu'!C53 | D12: ='SOFP-Sub-CuNonCu'!D53 | E12: ='SOFP-Sub-CuNonCu'!E53
A13: Investments in joint ventures | B13: ='SOFP-Sub-CuNonCu'!B60 | C13: ='SOFP-Sub-CuNonCu'!C60 | D13: ='SOFP-Sub-CuNonCu'!D60 | E13: ='SOFP-Sub-CuNonCu'!E60
A14: Other investments
A15: Trade and other non-current receivables | B15: ='SOFP-Sub-CuNonCu'!B84 | C15: ='SOFP-Sub-CuNonCu'!C84 | D15: ='SOFP-Sub-CuNonCu'!D84 | E15: ='SOFP-Sub-CuNonCu'!E84
A16: Deferred tax assets
A17: Other non-current assets
A18: *Total non-current assets | B18: =1*B7+1*B8+1*B9+1*B10+1*B11+1*B12+1*B13+1*B14+1*B15+1*B16+1*B17 | C18: =1*C7+1*C8+1*C9+1*C10+1*C11+1*C12+1*C13+1*C14+1*C15+1*C16+1*C17 | D18: =1*D7+1*D8+1*D9+1*D10+1*D11+1*D12+1*D13+1*D14+1*D15+1*D16+1*D17 | E18: =1*E7+1*E8+1*E9+1*E10+1*E11+1*E12+1*E13+1*E14+1*E15+1*E16+1*E17
A19: Current assets
A20: Inventories | B20: ='SOFP-Sub-CuNonCu'!B91 | C20: ='SOFP-Sub-CuNonCu'!C91 | D20: ='SOFP-Sub-CuNonCu'!D91 | E20: ='SOFP-Sub-CuNonCu'!E91
A21: Biological assets
A22: Other investments
A23: Trade and other current receivables | B23: ='SOFP-Sub-CuNonCu'!B122 | C23: ='SOFP-Sub-CuNonCu'!C122 | D23: ='SOFP-Sub-CuNonCu'!D122 | E23: ='SOFP-Sub-CuNonCu'!E122
A24: Current tax assets
A25: Derivative financial assets
A26: Cash and cash equivalents | B26: ='SOFP-Sub-CuNonCu'!B138 | C26: ='SOFP-Sub-CuNonCu'!C138 | D26: ='SOFP-Sub-CuNonCu'!D138 | E26: ='SOFP-Sub-CuNonCu'!E138
A27: Other current assets
A28: *Total current assets | B28: =1*B20+1*B21+1*B22+1*B23+1*B24+1*B25+1*B26+1*B27 | C28: =1*C20+1*C21+1*C22+1*C23+1*C24+1*C25+1*C26+1*C27 | D28: =1*D20+1*D21+1*D22+1*D23+1*D24+1*D25+1*D26+1*D27 | E28: =1*E20+1*E21+1*E22+1*E23+1*E24+1*E25+1*E26+1*E27
A29: *Total assets | B29: =1*B7+1*B8+1*B11+1*B12+1*B13+1*B14+1*B15+1*B16+1*B17+1*B20+1*B22+1*B23+1*B24+1*B25+1*B26+1*B27+1*B10+1*B9+1*B21 | C29: =1*C7+1*C8+1*C11+1*C12+1*C13+1*C14+1*C15+1*C16+1*C17+1*C20+1*C22+1*C23+1*C24+1*C25+1*C26+1*C27+1*C10+1*C9+1*C21 | D29: =1*D7+1*D8+1*D11+1*D12+1*D13+1*D14+1*D15+1*D16+1*D17+1*D20+1*D22+1*D23+1*D24+1*D25+1*D26+1*D27+1*D10+1*D9+1*D21 | E29: =1*E7+1*E8+1*E11+1*E12+1*E13+1*E14+1*E15+1*E16+1*E17+1*E20+1*E22+1*E23+1*E24+1*E25+1*E26+1*E27+1*E10+1*E9+1*E21
A30: Equity and liabilities
A31: Equity
A32: Issued capital | B32: ='SOFP-Sub-CuNonCu'!B143 | C32: ='SOFP-Sub-CuNonCu'!C143 | D32: ='SOFP-Sub-CuNonCu'!D143 | E32: ='SOFP-Sub-CuNonCu'!E143
A33: Retained earnings
A34: Treasury shares
A35: Reserves | B35: ='SOFP-Sub-CuNonCu'!B154 | C35: ='SOFP-Sub-CuNonCu'!C154 | D35: ='SOFP-Sub-CuNonCu'!D154 | E35: ='SOFP-Sub-CuNonCu'!E154
A36: *Total equity attributable to owners | B36: =1*B32+1*B33+-1*B34+1*B35 | C36: =1*C32+1*C33+-1*C34+1*C35 | D36: =1*D32+1*D33+-1*D34+1*D35 | E36: =1*E32+1*E33+-1*E34+1*E35
A37: Equity - other components | B37: ='SOFP-Sub-CuNonCu'!B160 | C37: ='SOFP-Sub-CuNonCu'!C160 | D37: ='SOFP-Sub-CuNonCu'!D160 | E37: ='SOFP-Sub-CuNonCu'!E160
A38: Non-controlling interests
A39: *Total equity | B39: =1*B32+1*B33+-1*B34+1*B35+1*B37+1*B38 | C39: =1*C32+1*C33+-1*C34+1*C35+1*C37+1*C38 | D39: =1*D32+1*D33+-1*D34+1*D35+1*D37+1*D38 | E39: =1*E32+1*E33+-1*E34+1*E35+1*E37+1*E38
A40: Liabilities
...

Sheet SOFP-Sub-CuNonCu
B1: Group | D1: Company | F1: Source
B2: 01/01/YYYY - 31/12/YYYY | C2: 01/01/YYYY - 31/12/YYYY | D2: 01/01/YYYY - 31/12/YYYY | E2: 01/01/YYYY - 31/12/YYYY
A3: Disclosure on sub-classification of assets, liabilities and equity
A4: Statement on sub-classification of assets, liabilities and equity
A5: Sub-classification of assets, liabilities and equity
A6: Property, plant and equipment
A7: Land and buildings
A8: Land
A9: Freehold land
A10: Long term leasehold land | B10: 12420 | C10: 12688 | D10: 12420 | E10: 12688
A11: Short term leasehold land
A12: *Total land | B12: =1*B9+1*B10+1*B11 | C12: =1*C9+1*C10+1*C11 | D12: =1*D9+1*D10+1*D11 | E12: =1*E9+1*E10+1*E11
A13: Buildings
A14: Building on freehold land
A15: Building on long term leasehold land | B15: 23345 | C15: 23978 | D15: 23345 | E15: 23978
A16: Building on short term leasehold land
A17: Leased properties
A18: *Total buildings | B18: =1*B14+1*B15+1*B16+1*B17 | C18: =1*C14+1*C15+1*C16+1*C17 | D18: =1*D14+1*D15+1*D16+1*D17 | E18: =1*E14+1*E15+1*E16+1*E17
A19: *Total land and buildings | B19: =1*B12+1*B18 | C19: =1*C12+1*C18 | D19: =1*D12+1*D18 | E19: =1*E12+1*E18
A20: Machinery
A21: Vehicles
A22: Office equipment, fixture and fittings | B22: 16958 | C22: 9906 | D22: 16958 | E22: 9906
A23: Plant and equipment
A24: Construction in progress/Asset work-in progress | B24: 2275 | D24: 2275
A25: Other property, plant and equipment | B25: 9525 | C25: 9592 | D25: 9525 | E25: 9592
A26: *Total property, plant and equipment | B26: =1*B19+1*B20+1*B21+1*B22+1*B23+1*B24+1*B25 | C26: =1*C19+1*C20+1*C21+1*C22+1*C23+1*C24+1*C25 | D26: =1*D19+1*D20+1*D21+1*D22+1*D23+1*D24+1*D25 | E26: =1*E19+1*E20+1*E21+1*E22+1*E23+1*E24+1*E25
A27: Investment properties
A28: Freehold land
A29: Long term leasehold land
A30: Short term leasehold land
A31: Buildings
A32: Other investment property
A33: *Total investment properties | B33: =1*B28+1*B29+1*B30+1*B31+1*B32 | C33: =1*C28+1*C29+1*C30+1*C31+1*C32 | D33: =1*D28+1*D29+1*D30+1*D31+1*D32 | E33: =1*E28+1*E29+1*E30+1*E31+1*E32
A34: Intangible assets and goodwill
A35: Intangible assets other than goodwill
A36: Copyrights, patents and other industrial property rights, service and operating rights
A37: Other intangible assets
A38: *Total intangible assets other than goodwill | B38: =1*B36+1*B37 | C38: =1*C36+1*C37 | D38: =1*D36+1*D37 | E38: =1*E36+1*E37
A39: Goodwill
A40: *Total intangible assets and goodwill | B40: =1*B39+1*B38 | C40: =1*C39+1*C38 | D40: =1*D39+1*D38 | E40: =1*E39+1*E38
...
